{
    DataVersion: 3465,
    size: [48, 11, 48],
    data: [
        {pos: [23, 2, 19], state: "dustandash:cobblestone_with_moss"},
        {pos: [23, 2, 20], state: "dustandash:cobblestone_with_moss"},
        {pos: [23, 2, 21], state: "dustandash:cobblestone_with_moss"},
        {pos: [23, 2, 22], state: "dustandash:cobblestone_with_moss"},
        {pos: [23, 2, 23], state: "dustandash:cobblestone_with_moss"},
        {pos: [24, 2, 19], state: "dustandash:cobblestone_with_moss"},
        {pos: [24, 2, 20], state: "minecraft:moss_block"},
        {pos: [24, 2, 21], state: "dustandash:cobblestone_with_moss"},
        {pos: [24, 2, 22], state: "dustandash:cobblestone_with_moss"},
        {pos: [24, 2, 23], state: "dustandash:cobblestone_with_moss"},
        {pos: [25, 2, 19], state: "dustandash:cobblestone_with_moss"},
        {pos: [25, 2, 20], state: "dustandash:cobblestone_with_moss"},
        {pos: [25, 2, 21], state: "minecraft:moss_block"},
        {pos: [25, 2, 22], state: "dustandash:cobblestone_with_moss"},
        {pos: [25, 2, 23], state: "dustandash:cobblestone_with_moss"},
        {pos: [26, 2, 20], state: "dustandash:cobblestone_with_moss"},
        {pos: [26, 2, 21], state: "minecraft:moss_block"},
        {pos: [26, 2, 22], state: "dustandash:cobblestone_with_moss"},
        {pos: [27, 2, 21], state: "minecraft:moss_block"},
        {pos: [20, 3, 21], state: "minecraft:moss_block"},
        {pos: [20, 3, 22], state: "minecraft:moss_block"},
        {pos: [21, 3, 21], state: "minecraft:moss_block"},
        {pos: [21, 3, 22], state: "minecraft:moss_block"},
        {pos: [22, 3, 17], state: "minecraft:moss_block"},
        {pos: [22, 3, 18], state: "minecraft:moss_block"},
        {pos: [22, 3, 19], state: "minecraft:moss_block"},
        {pos: [22, 3, 20], state: "minecraft:moss_block"},
        {pos: [22, 3, 21], state: "minecraft:moss_block"},
        {pos: [22, 3, 22], state: "minecraft:moss_block"},
        {pos: [22, 3, 23], state: "minecraft:moss_block"},
        {pos: [23, 3, 15], state: "minecraft:moss_block"},
        {pos: [23, 3, 16], state: "minecraft:moss_block"},
        {pos: [23, 3, 17], state: "minecraft:moss_block"},
        {pos: [23, 3, 18], state: "minecraft:moss_block"},
        {pos: [23, 3, 19], state: "minecraft:moss_block"},
        {pos: [23, 3, 20], state: "minecraft:moss_block"},
        {pos: [23, 3, 21], state: "minecraft:moss_block"},
        {pos: [23, 3, 22], state: "minecraft:moss_block"},
        {pos: [23, 3, 23], state: "minecraft:moss_block"},
        {pos: [23, 3, 24], state: "minecraft:moss_block"},
        {pos: [24, 3, 15], state: "minecraft:moss_block"},
        {pos: [24, 3, 16], state: "minecraft:moss_block"},
        {pos: [24, 3, 18], state: "minecraft:moss_block"},
        {pos: [24, 3, 19], state: "minecraft:moss_block"},
        {pos: [24, 3, 20], state: "minecraft:moss_block"},
        {pos: [24, 3, 21], state: "minecraft:moss_block"},
        {pos: [24, 3, 22], state: "minecraft:moss_block"},
        {pos: [24, 3, 23], state: "minecraft:moss_block"},
        {pos: [24, 3, 24], state: "minecraft:moss_block"},
        {pos: [25, 3, 18], state: "minecraft:moss_block"},
        {pos: [25, 3, 19], state: "dustandash:cobblestone_with_moss"},
        {pos: [25, 3, 20], state: "minecraft:moss_block"},
        {pos: [25, 3, 21], state: "minecraft:cobblestone"},
        {pos: [25, 3, 22], state: "minecraft:moss_block"},
        {pos: [25, 3, 23], state: "dustandash:cobblestone_with_moss"},
        {pos: [25, 3, 24], state: "minecraft:moss_block"},
        {pos: [26, 3, 18], state: "minecraft:moss_block"},
        {pos: [26, 3, 19], state: "dustandash:cobblestone_with_moss"},
        {pos: [26, 3, 20], state: "dustandash:cobblestone_with_moss"},
        {pos: [26, 3, 21], state: "minecraft:moss_block"},
        {pos: [26, 3, 22], state: "minecraft:cobblestone"},
        {pos: [26, 3, 23], state: "minecraft:cobblestone"},
        {pos: [26, 3, 24], state: "minecraft:moss_block"},
        {pos: [26, 3, 25], state: "minecraft:moss_block"},
        {pos: [26, 3, 26], state: "minecraft:moss_block"},
        {pos: [27, 3, 18], state: "minecraft:moss_block"},
        {pos: [27, 3, 19], state: "minecraft:moss_block"},
        {pos: [27, 3, 20], state: "dustandash:cobblestone_with_moss"},
        {pos: [27, 3, 21], state: "minecraft:cobblestone"},
        {pos: [27, 3, 22], state: "minecraft:moss_block"},
        {pos: [27, 3, 23], state: "minecraft:moss_block"},
        {pos: [27, 3, 24], state: "minecraft:moss_block"},
        {pos: [27, 3, 25], state: "minecraft:moss_block"},
        {pos: [28, 3, 19], state: "minecraft:moss_block"},
        {pos: [28, 3, 20], state: "minecraft:moss_block"},
        {pos: [28, 3, 21], state: "minecraft:moss_block"},
        {pos: [28, 3, 22], state: "minecraft:moss_block"},
        {pos: [28, 3, 23], state: "minecraft:moss_block"},
        {pos: [29, 3, 21], state: "minecraft:moss_block"},
        {pos: [29, 3, 22], state: "minecraft:moss_block"},
        {pos: [15, 4, 25], state: "minecraft:hanging_roots{waterlogged:false}"},
        {pos: [16, 4, 15], state: "minecraft:hanging_roots{waterlogged:false}"},
        {pos: [16, 4, 29], state: "minecraft:hanging_roots{waterlogged:false}"},
        {pos: [18, 4, 13], state: "minecraft:hanging_roots{waterlogged:false}"},
        {pos: [18, 4, 29], state: "minecraft:hanging_roots{waterlogged:false}"},
        {pos: [19, 4, 22], state: "minecraft:moss_block"},
        {pos: [19, 4, 29], state: "minecraft:hanging_roots{waterlogged:false}"},
        {pos: [20, 4, 12], state: "minecraft:hanging_roots{waterlogged:false}"},
        {pos: [20, 4, 21], state: "minecraft:moss_block"},
        {pos: [20, 4, 22], state: "minecraft:moss_block"},
        {pos: [20, 4, 29], state: "minecraft:moss_block"},
        {pos: [21, 4, 21], state: "minecraft:moss_block"},
        {pos: [21, 4, 30], state: "minecraft:moss_block"},
        {pos: [22, 4, 20], state: "minecraft:moss_carpet"},
        {pos: [22, 4, 21], state: "minecraft:moss_carpet"},
        {pos: [22, 4, 22], state: "minecraft:grass"},
        {pos: [23, 4, 13], state: "minecraft:moss_block"},
        {pos: [23, 4, 14], state: "minecraft:moss_block"},
        {pos: [23, 4, 15], state: "minecraft:moss_block"},
        {pos: [23, 4, 17], state: "minecraft:tall_grass{half:lower}"},
        {pos: [24, 4, 15], state: "minecraft:moss_block"},
        {pos: [24, 4, 16], state: "minecraft:grass"},
        {pos: [24, 4, 19], state: "minecraft:moss_carpet"},
        {pos: [24, 4, 22], state: "minecraft:moss_carpet"},
        {pos: [24, 4, 23], state: "minecraft:azalea"},
        {pos: [25, 4, 13], state: "minecraft:hanging_roots{waterlogged:false}"},
        {pos: [25, 4, 19], state: "minecraft:moss_carpet"},
        {pos: [25, 4, 22], state: "quark:azalea_chest{facing:north,type:left,waterlogged:false}", nbt: {ForgeCaps: {}, Items: [{Count: 1b, Slot: 0b, id: "minecraft:gravel"}, {Count: 1b, Slot: 1b, id: "minecraft:cobweb"}, {Count: 1b, Slot: 2b, id: "minecraft:cobweb"}, {Count: 1b, Slot: 3b, id: "minecraft:string"}, {Count: 1b, Slot: 4b, id: "minecraft:string"}, {Count: 1b, Slot: 5b, id: "minecraft:string"}, {Count: 1b, Slot: 6b, id: "minecraft:bone_meal"}, {Count: 2b, Slot: 7b, id: "minecraft:bone_meal"}, {Count: 2b, Slot: 8b, id: "minecraft:sand"}, {Count: 1b, Slot: 9b, id: "minecraft:gravel"}, {Count: 1b, Slot: 10b, id: "tetra:modular_double", tag: {Damage: 0, "double/basic_hammer_left_material": "basic_hammer/stone", "double/basic_hammer_right_material": "basic_hammer/stone", "double/basic_handle_material": "basic_handle/stick", "double/handle": "double/basic_handle", "double/head_left": "double/basic_hammer_left", "double/head_right": "double/basic_hammer_right", id: "c4fba8e7-d86a-403b-81ec-9d7b65bd8459"}}, {Count: 1b, Slot: 11b, id: "minecraft:bucket"}, {Count: 1b, Slot: 12b, id: "minecraft:cobweb"}, {Count: 1b, Slot: 13b, id: "minecraft:cobweb"}, {Count: 3b, Slot: 14b, id: "minecraft:bone_meal"}, {Count: 3b, Slot: 15b, id: "minecraft:bone_meal"}, {Count: 1b, Slot: 16b, id: "slashblade:proudsoul_ingot"}, {Count: 1b, Slot: 17b, id: "minecraft:string"}, {Count: 1b, Slot: 18b, id: "minecraft:string"}, {Count: 1b, Slot: 19b, id: "minecraft:cobweb"}, {Count: 2b, Slot: 20b, id: "minecraft:gravel"}, {Count: 1b, Slot: 21b, id: "minecraft:cobweb"}, {Count: 1b, Slot: 22b, id: "minecraft:bone_meal"}, {Count: 1b, Slot: 23b, id: "minecraft:bone_meal"}, {Count: 2b, Slot: 24b, id: "minecraft:sand"}, {Count: 1b, Slot: 25b, id: "minecraft:bone_meal"}, {Count: 3b, Slot: 26b, id: "minecraft:sand"}], id: "quark:variant_chest"}},
        {pos: [25, 4, 23], state: "minecraft:moss_carpet"},
        {pos: [26, 4, 16], state: "minecraft:moss_block"},
        {pos: [26, 4, 17], state: "minecraft:moss_block"},
        {pos: [26, 4, 18], state: "minecraft:moss_block"},
        {pos: [26, 4, 21], state: "minecraft:moss_carpet"},
        {pos: [26, 4, 22], state: "quark:azalea_chest{facing:north,type:right,waterlogged:false}", nbt: {ForgeCaps: {}, Items: [{Count: 1b, Slot: 1b, id: "minecraft:string"}, {Count: 1b, Slot: 2b, id: "minecraft:gravel"}, {Count: 1b, Slot: 3b, id: "minecraft:gravel"}, {Count: 1b, Slot: 4b, id: "minecraft:string"}, {Count: 1b, Slot: 5b, id: "minecraft:bucket"}, {Count: 2b, Slot: 6b, id: "minecraft:sand"}, {Count: 1b, Slot: 7b, id: "minecraft:bone_meal"}, {Count: 1b, Slot: 8b, id: "minecraft:gravel"}, {Count: 1b, Slot: 9b, id: "minecraft:bone_meal"}, {Count: 1b, Slot: 10b, id: "minecraft:cobweb"}, {Count: 1b, Slot: 11b, id: "powerful_dummy:dummy_stand"}, {Count: 1b, Slot: 12b, id: "minecraft:cobweb"}, {Count: 1b, Slot: 13b, id: "minecraft:bone_meal"}, {Count: 1b, Slot: 14b, id: "minecraft:string"}, {Count: 1b, Slot: 15b, id: "minecraft:cobweb"}, {Count: 3b, Slot: 16b, id: "minecraft:sand"}, {Count: 1b, Slot: 17b, id: "minecraft:bone_meal"}, {Count: 2b, Slot: 18b, id: "minecraft:bone_meal"}, {Count: 3b, Slot: 19b, id: "minecraft:bone_meal"}, {Count: 3b, Slot: 20b, id: "minecraft:gravel"}, {Count: 2b, Slot: 21b, id: "minecraft:sand"}, {Count: 2b, Slot: 22b, id: "minecraft:gravel"}, {Count: 1b, Slot: 23b, id: "minecraft:bone_meal"}, {Count: 1b, Slot: 24b, id: "minecraft:bone_meal"}, {Count: 1b, Slot: 25b, id: "minecraft:string"}, {Count: 1b, Slot: 26b, id: "minecraft:cobweb"}], id: "quark:variant_chest"}},
        {pos: [26, 4, 23], state: "minecraft:composter{level:5}"},
        {pos: [26, 4, 24], state: "minecraft:moss_carpet"},
        {pos: [26, 4, 26], state: "minecraft:moss_block"},
        {pos: [26, 4, 27], state: "minecraft:moss_block"},
        {pos: [26, 4, 28], state: "minecraft:hanging_roots{waterlogged:false}"},
        {pos: [27, 4, 19], state: "quark:azalea_fence{east:false,north:false,south:false,waterlogged:false,west:false}"},
        {pos: [27, 4, 20], state: "minecraft:moss_carpet"},
        {pos: [27, 4, 22], state: "quark:azalea_fence{east:false,north:false,south:true,waterlogged:false,west:false}"},
        {pos: [27, 4, 23], state: "minecraft:moss_block"},
        {pos: [27, 4, 24], state: "minecraft:moss_block"},
        {pos: [27, 4, 25], state: "minecraft:moss_block"},
        {pos: [27, 4, 26], state: "minecraft:moss_block"},
        {pos: [28, 4, 14], state: "minecraft:hanging_roots{waterlogged:false}"},
        {pos: [28, 4, 23], state: "minecraft:moss_block"},
        {pos: [29, 4, 22], state: "minecraft:moss_block"},
        {pos: [30, 4, 22], state: "minecraft:moss_block"},
        {pos: [31, 4, 22], state: "minecraft:moss_block"},
        {pos: [31, 4, 23], state: "minecraft:moss_block"},
        {pos: [31, 4, 31], state: "minecraft:hanging_roots{waterlogged:false}"},
        {pos: [32, 4, 23], state: "minecraft:moss_block"},
        {pos: [33, 4, 23], state: "minecraft:moss_block"},
        {pos: [34, 4, 30], state: "minecraft:hanging_roots{waterlogged:false}"},
        {pos: [37, 4, 19], state: "minecraft:hanging_roots{waterlogged:false}"},
        {pos: [14, 5, 22], state: "minecraft:hanging_roots{waterlogged:false}"},
        {pos: [14, 5, 23], state: "minecraft:moss_block"},
        {pos: [15, 5, 19], state: "minecraft:hanging_roots{waterlogged:false}"},
        {pos: [15, 5, 20], state: "minecraft:moss_block"},
        {pos: [15, 5, 22], state: "minecraft:moss_block"},
        {pos: [15, 5, 23], state: "minecraft:moss_block"},
        {pos: [15, 5, 24], state: "minecraft:moss_block"},
        {pos: [15, 5, 25], state: "minecraft:moss_block"},
        {pos: [15, 5, 27], state: "minecraft:moss_block"},
        {pos: [16, 5, 15], state: "minecraft:moss_block"},
        {pos: [16, 5, 16], state: "minecraft:moss_block"},
        {pos: [16, 5, 18], state: "minecraft:moss_block"},
        {pos: [16, 5, 21], state: "minecraft:moss_block"},
        {pos: [16, 5, 22], state: "minecraft:moss_block"},
        {pos: [16, 5, 23], state: "minecraft:moss_block"},
        {pos: [16, 5, 24], state: "minecraft:moss_block"},
        {pos: [16, 5, 25], state: "minecraft:moss_block"},
        {pos: [16, 5, 26], state: "minecraft:moss_block"},
        {pos: [16, 5, 27], state: "minecraft:moss_block"},
        {pos: [16, 5, 28], state: "minecraft:moss_block"},
        {pos: [16, 5, 29], state: "minecraft:moss_block"},
        {pos: [17, 5, 16], state: "minecraft:moss_block"},
        {pos: [17, 5, 17], state: "minecraft:moss_block"},
        {pos: [17, 5, 18], state: "minecraft:moss_block"},
        {pos: [17, 5, 19], state: "minecraft:moss_block"},
        {pos: [17, 5, 20], state: "minecraft:moss_block"},
        {pos: [17, 5, 21], state: "minecraft:moss_block"},
        {pos: [17, 5, 22], state: "minecraft:moss_block"},
        {pos: [17, 5, 23], state: "minecraft:moss_block"},
        {pos: [17, 5, 24], state: "minecraft:moss_block"},
        {pos: [17, 5, 27], state: "minecraft:moss_block"},
        {pos: [17, 5, 28], state: "minecraft:moss_block"},
        {pos: [18, 5, 12], state: "minecraft:moss_block"},
        {pos: [18, 5, 13], state: "minecraft:moss_block"},
        {pos: [18, 5, 14], state: "minecraft:moss_block"},
        {pos: [18, 5, 15], state: "minecraft:moss_block"},
        {pos: [18, 5, 16], state: "minecraft:moss_block"},
        {pos: [18, 5, 17], state: "minecraft:moss_block"},
        {pos: [18, 5, 18], state: "minecraft:moss_block"},
        {pos: [18, 5, 19], state: "minecraft:moss_block"},
        {pos: [18, 5, 21], state: "minecraft:moss_block"},
        {pos: [18, 5, 22], state: "minecraft:moss_block"},
        {pos: [18, 5, 24], state: "minecraft:moss_block"},
        {pos: [18, 5, 25], state: "minecraft:moss_block"},
        {pos: [18, 5, 26], state: "minecraft:moss_block"},
        {pos: [18, 5, 28], state: "minecraft:moss_block"},
        {pos: [18, 5, 29], state: "minecraft:moss_block"},
        {pos: [18, 5, 30], state: "minecraft:moss_block"},
        {pos: [19, 5, 13], state: "minecraft:moss_block"},
        {pos: [19, 5, 14], state: "minecraft:moss_block"},
        {pos: [19, 5, 15], state: "minecraft:moss_block"},
        {pos: [19, 5, 16], state: "minecraft:moss_block"},
        {pos: [19, 5, 21], state: "minecraft:moss_block"},
        {pos: [19, 5, 22], state: "minecraft:moss_block"},
        {pos: [19, 5, 26], state: "minecraft:moss_block"},
        {pos: [19, 5, 27], state: "minecraft:moss_block"},
        {pos: [19, 5, 28], state: "minecraft:moss_block"},
        {pos: [19, 5, 29], state: "minecraft:moss_block"},
        {pos: [19, 5, 30], state: "minecraft:moss_block"},
        {pos: [19, 5, 31], state: "minecraft:moss_block"},
        {pos: [20, 5, 11], state: "minecraft:moss_block"},
        {pos: [20, 5, 12], state: "minecraft:moss_block"},
        {pos: [20, 5, 13], state: "minecraft:moss_block"},
        {pos: [20, 5, 14], state: "minecraft:moss_block"},
        {pos: [20, 5, 21], state: "minecraft:moss_block"},
        {pos: [20, 5, 27], state: "minecraft:moss_block"},
        {pos: [20, 5, 28], state: "minecraft:moss_block"},
        {pos: [20, 5, 29], state: "minecraft:water{level:8}"},
        {pos: [20, 5, 30], state: "minecraft:cobblestone"},
        {pos: [21, 5, 12], state: "minecraft:moss_block"},
        {pos: [21, 5, 13], state: "minecraft:moss_block"},
        {pos: [21, 5, 27], state: "minecraft:moss_block"},
        {pos: [21, 5, 28], state: "minecraft:moss_block"},
        {pos: [21, 5, 29], state: "minecraft:moss_block"},
        {pos: [21, 5, 30], state: "minecraft:cobblestone"},
        {pos: [21, 5, 31], state: "minecraft:cobblestone"},
        {pos: [22, 5, 11], state: "minecraft:moss_block"},
        {pos: [22, 5, 12], state: "minecraft:moss_block"},
        {pos: [22, 5, 13], state: "minecraft:moss_block"},
        {pos: [22, 5, 29], state: "minecraft:moss_block"},
        {pos: [22, 5, 30], state: "minecraft:cobblestone"},
        {pos: [22, 5, 31], state: "minecraft:moss_block"},
        {pos: [23, 5, 12], state: "minecraft:moss_block"},
        {pos: [23, 5, 13], state: "minecraft:moss_block"},
        {pos: [23, 5, 14], state: "minecraft:tall_grass{half:lower}"},
        {pos: [23, 5, 15], state: "minecraft:azalea"},
        {pos: [23, 5, 17], state: "minecraft:tall_grass{half:upper}"},
        {pos: [23, 5, 29], state: "minecraft:moss_block"},
        {pos: [23, 5, 30], state: "minecraft:moss_block"},
        {pos: [23, 5, 31], state: "minecraft:cobblestone"},
        {pos: [24, 5, 12], state: "minecraft:moss_block"},
        {pos: [24, 5, 13], state: "minecraft:moss_block"},
        {pos: [24, 5, 14], state: "minecraft:moss_block"},
        {pos: [24, 5, 15], state: "minecraft:moss_block"},
        {pos: [24, 5, 28], state: "minecraft:moss_block"},
        {pos: [24, 5, 29], state: "minecraft:moss_block"},
        {pos: [24, 5, 30], state: "minecraft:moss_block"},
        {pos: [24, 5, 31], state: "minecraft:cobblestone"},
        {pos: [25, 5, 12], state: "minecraft:moss_block"},
        {pos: [25, 5, 13], state: "minecraft:moss_block"},
        {pos: [25, 5, 28], state: "minecraft:moss_block"},
        {pos: [25, 5, 29], state: "minecraft:moss_block"},
        {pos: [25, 5, 30], state: "minecraft:moss_block"},
        {pos: [25, 5, 31], state: "minecraft:moss_block"},
        {pos: [26, 5, 12], state: "minecraft:moss_block"},
        {pos: [26, 5, 13], state: "minecraft:moss_block"},
        {pos: [26, 5, 15], state: "minecraft:moss_block"},
        {pos: [26, 5, 16], state: "minecraft:moss_block"},
        {pos: [26, 5, 22], state: "quark:azalea_fence{east:true,north:false,south:false,waterlogged:false,west:false}"},
        {pos: [26, 5, 27], state: "minecraft:moss_block"},
        {pos: [26, 5, 28], state: "minecraft:moss_block"},
        {pos: [26, 5, 29], state: "minecraft:moss_block"},
        {pos: [26, 5, 30], state: "minecraft:moss_block"},
        {pos: [26, 5, 31], state: "minecraft:moss_block"},
        {pos: [26, 5, 32], state: "minecraft:moss_block"},
        {pos: [26, 5, 33], state: "minecraft:moss_block"},
        {pos: [27, 5, 13], state: "minecraft:moss_block"},
        {pos: [27, 5, 14], state: "minecraft:moss_block"},
        {pos: [27, 5, 15], state: "minecraft:moss_block"},
        {pos: [27, 5, 19], state: "quark:azalea_fence{east:false,north:false,south:false,waterlogged:false,west:false}"},
        {pos: [27, 5, 22], state: "quark:azalea_fence{east:false,north:false,south:false,waterlogged:false,west:true}"},
        {pos: [27, 5, 24], state: "minecraft:moss_carpet"},
        {pos: [27, 5, 25], state: "minecraft:grass"},
        {pos: [27, 5, 26], state: "minecraft:grass"},
        {pos: [27, 5, 27], state: "minecraft:moss_block"},
        {pos: [27, 5, 28], state: "minecraft:moss_block"},
        {pos: [27, 5, 29], state: "minecraft:moss_block"},
        {pos: [27, 5, 30], state: "minecraft:moss_block"},
        {pos: [27, 5, 32], state: "minecraft:moss_block"},
        {pos: [28, 5, 13], state: "minecraft:moss_block"},
        {pos: [28, 5, 14], state: "minecraft:moss_block"},
        {pos: [28, 5, 23], state: "minecraft:moss_block"},
        {pos: [28, 5, 24], state: "minecraft:moss_block"},
        {pos: [28, 5, 25], state: "minecraft:moss_block"},
        {pos: [28, 5, 28], state: "minecraft:moss_block"},
        {pos: [28, 5, 29], state: "minecraft:moss_block"},
        {pos: [28, 5, 30], state: "minecraft:moss_block"},
        {pos: [29, 5, 13], state: "minecraft:moss_block"},
        {pos: [29, 5, 14], state: "minecraft:moss_block"},
        {pos: [29, 5, 15], state: "minecraft:moss_block"},
        {pos: [29, 5, 16], state: "minecraft:moss_block"},
        {pos: [29, 5, 23], state: "minecraft:moss_block"},
        {pos: [29, 5, 24], state: "minecraft:moss_block"},
        {pos: [29, 5, 25], state: "minecraft:moss_block"},
        {pos: [29, 5, 26], state: "minecraft:moss_block"},
        {pos: [29, 5, 27], state: "minecraft:moss_block"},
        {pos: [29, 5, 28], state: "minecraft:moss_block"},
        {pos: [29, 5, 30], state: "minecraft:moss_block"},
        {pos: [30, 5, 16], state: "minecraft:moss_block"},
        {pos: [30, 5, 17], state: "minecraft:moss_block"},
        {pos: [30, 5, 23], state: "minecraft:moss_block"},
        {pos: [30, 5, 24], state: "minecraft:moss_block"},
        {pos: [30, 5, 25], state: "minecraft:moss_block"},
        {pos: [30, 5, 30], state: "minecraft:moss_block"},
        {pos: [30, 5, 31], state: "minecraft:moss_block"},
        {pos: [30, 5, 32], state: "minecraft:moss_block"},
        {pos: [31, 5, 12], state: "minecraft:moss_block"},
        {pos: [31, 5, 16], state: "minecraft:moss_block"},
        {pos: [31, 5, 17], state: "minecraft:moss_block"},
        {pos: [31, 5, 23], state: "minecraft:grass"},
        {pos: [31, 5, 24], state: "minecraft:moss_block"},
        {pos: [31, 5, 31], state: "minecraft:moss_block"},
        {pos: [31, 5, 32], state: "minecraft:moss_block"},
        {pos: [31, 5, 35], state: "minecraft:hanging_roots{waterlogged:false}"},
        {pos: [32, 5, 16], state: "minecraft:hanging_roots{waterlogged:false}"},
        {pos: [32, 5, 17], state: "minecraft:moss_block"},
        {pos: [32, 5, 18], state: "minecraft:moss_block"},
        {pos: [32, 5, 23], state: "minecraft:grass"},
        {pos: [32, 5, 24], state: "minecraft:moss_block"},
        {pos: [32, 5, 31], state: "minecraft:moss_block"},
        {pos: [33, 5, 18], state: "minecraft:moss_block"},
        {pos: [33, 5, 19], state: "minecraft:moss_block"},
        {pos: [33, 5, 23], state: "minecraft:moss_block"},
        {pos: [33, 5, 24], state: "minecraft:moss_block"},
        {pos: [33, 5, 25], state: "minecraft:moss_block"},
        {pos: [33, 5, 31], state: "minecraft:moss_block"},
        {pos: [34, 5, 19], state: "minecraft:moss_block"},
        {pos: [34, 5, 20], state: "minecraft:moss_block"},
        {pos: [34, 5, 24], state: "minecraft:moss_block"},
        {pos: [34, 5, 25], state: "minecraft:moss_block"},
        {pos: [34, 5, 28], state: "minecraft:moss_block"},
        {pos: [34, 5, 29], state: "minecraft:moss_block"},
        {pos: [34, 5, 30], state: "minecraft:moss_block"},
        {pos: [34, 5, 31], state: "minecraft:moss_block"},
        {pos: [35, 5, 15], state: "minecraft:moss_block"},
        {pos: [35, 5, 20], state: "minecraft:moss_block"},
        {pos: [35, 5, 24], state: "minecraft:moss_block"},
        {pos: [35, 5, 25], state: "minecraft:moss_block"},
        {pos: [35, 5, 26], state: "minecraft:moss_block"},
        {pos: [35, 5, 27], state: "minecraft:moss_block"},
        {pos: [35, 5, 28], state: "minecraft:moss_block"},
        {pos: [35, 5, 34], state: "minecraft:hanging_roots{waterlogged:false}"},
        {pos: [36, 5, 20], state: "minecraft:moss_block"},
        {pos: [36, 5, 22], state: "minecraft:moss_block"},
        {pos: [36, 5, 23], state: "minecraft:moss_block"},
        {pos: [36, 5, 24], state: "minecraft:moss_block"},
        {pos: [36, 5, 25], state: "minecraft:moss_block"},
        {pos: [36, 5, 26], state: "minecraft:moss_block"},
        {pos: [36, 5, 27], state: "minecraft:moss_block"},
        {pos: [37, 5, 19], state: "minecraft:moss_block"},
        {pos: [37, 5, 20], state: "minecraft:moss_block"},
        {pos: [37, 5, 21], state: "minecraft:moss_block"},
        {pos: [37, 5, 22], state: "minecraft:moss_block"},
        {pos: [37, 5, 28], state: "minecraft:hanging_roots{waterlogged:false}"},
        {pos: [38, 5, 22], state: "minecraft:moss_block"},
        {pos: [39, 5, 18], state: "minecraft:moss_block"},
        {pos: [39, 5, 21], state: "minecraft:hanging_roots{waterlogged:false}"},
        {pos: [39, 5, 25], state: "minecraft:hanging_roots{waterlogged:false}"},
        {pos: [14, 6, 21], state: "minecraft:stone"},
        {pos: [14, 6, 22], state: "minecraft:cobblestone"},
        {pos: [14, 6, 23], state: "minecraft:stone"},
        {pos: [14, 6, 27], state: "minecraft:cobblestone"},
        {pos: [15, 6, 17], state: "minecraft:cobblestone"},
        {pos: [15, 6, 18], state: "minecraft:stone"},
        {pos: [15, 6, 19], state: "minecraft:stone"},
        {pos: [15, 6, 20], state: "dustandash:cobblestone_with_moss"},
        {pos: [15, 6, 21], state: "dustandash:cobblestone_with_moss"},
        {pos: [15, 6, 22], state: "dustandash:cobblestone_with_moss"},
        {pos: [15, 6, 23], state: "dustandash:cobblestone_with_moss"},
        {pos: [15, 6, 24], state: "dustandash:cobblestone_with_moss"},
        {pos: [15, 6, 25], state: "dustandash:cobblestone_with_moss"},
        {pos: [15, 6, 26], state: "dustandash:cobblestone_with_moss"},
        {pos: [15, 6, 27], state: "dustandash:cobblestone_with_moss"},
        {pos: [16, 6, 14], state: "minecraft:cobblestone"},
        {pos: [16, 6, 15], state: "minecraft:cobblestone"},
        {pos: [16, 6, 16], state: "dustandash:cobblestone_with_moss"},
        {pos: [16, 6, 17], state: "dustandash:cobblestone_with_moss"},
        {pos: [16, 6, 18], state: "dustandash:cobblestone_with_moss"},
        {pos: [16, 6, 19], state: "dustandash:cobblestone_with_moss"},
        {pos: [16, 6, 20], state: "dustandash:cobblestone_with_moss"},
        {pos: [16, 6, 21], state: "minecraft:moss_block"},
        {pos: [16, 6, 22], state: "minecraft:moss_block"},
        {pos: [16, 6, 23], state: "minecraft:moss_block"},
        {pos: [16, 6, 24], state: "minecraft:moss_block"},
        {pos: [16, 6, 25], state: "minecraft:moss_block"},
        {pos: [16, 6, 26], state: "dustandash:cobblestone_with_moss"},
        {pos: [16, 6, 27], state: "dustandash:cobblestone_with_moss"},
        {pos: [16, 6, 28], state: "dustandash:cobblestone_with_moss"},
        {pos: [16, 6, 29], state: "dustandash:cobblestone_with_moss"},
        {pos: [16, 6, 30], state: "minecraft:cobblestone"},
        {pos: [17, 6, 13], state: "dustandash:cobblestone_with_moss"},
        {pos: [17, 6, 14], state: "dustandash:cobblestone_with_moss"},
        {pos: [17, 6, 15], state: "dustandash:cobblestone_with_moss"},
        {pos: [17, 6, 16], state: "minecraft:moss_block"},
        {pos: [17, 6, 17], state: "minecraft:moss_block"},
        {pos: [17, 6, 18], state: "minecraft:moss_block"},
        {pos: [17, 6, 20], state: "minecraft:moss_block"},
        {pos: [17, 6, 21], state: "minecraft:moss_carpet"},
        {pos: [17, 6, 22], state: "minecraft:grass"},
        {pos: [17, 6, 27], state: "minecraft:tall_grass{half:lower}"},
        {pos: [17, 6, 28], state: "dustandash:cobblestone_with_moss"},
        {pos: [17, 6, 29], state: "dustandash:cobblestone_with_moss"},
        {pos: [17, 6, 30], state: "dustandash:cobblestone_with_moss"},
        {pos: [18, 6, 11], state: "minecraft:cobblestone"},
        {pos: [18, 6, 12], state: "dustandash:cobblestone_with_moss"},
        {pos: [18, 6, 13], state: "dustandash:cobblestone_with_moss"},
        {pos: [18, 6, 14], state: "minecraft:moss_block"},
        {pos: [18, 6, 15], state: "minecraft:moss_block"},
        {pos: [18, 6, 19], state: "minecraft:flowering_azalea"},
        {pos: [18, 6, 21], state: "minecraft:grass"},
        {pos: [18, 6, 22], state: "minecraft:grass"},
        {pos: [18, 6, 24], state: "minecraft:grass"},
        {pos: [18, 6, 26], state: "minecraft:grass"},
        {pos: [18, 6, 29], state: "dustandash:cobblestone_with_moss"},
        {pos: [18, 6, 30], state: "dustandash:cobblestone_with_moss"},
        {pos: [18, 6, 31], state: "minecraft:cobblestone"},
        {pos: [19, 6, 10], state: "minecraft:stone"},
        {pos: [19, 6, 11], state: "minecraft:cobblestone"},
        {pos: [19, 6, 12], state: "dustandash:cobblestone_with_moss"},
        {pos: [19, 6, 13], state: "minecraft:moss_block"},
        {pos: [19, 6, 14], state: "minecraft:tall_grass{half:lower}"},
        {pos: [19, 6, 15], state: "minecraft:grass"},
        {pos: [19, 6, 16], state: "minecraft:grass"},
        {pos: [19, 6, 26], state: "minecraft:grass"},
        {pos: [19, 6, 29], state: "minecraft:moss_block"},
        {pos: [19, 6, 30], state: "dustandash:cobblestone_with_moss"},
        {pos: [19, 6, 31], state: "dustandash:cobblestone_with_moss"},
        {pos: [19, 6, 34], state: "minecraft:hanging_roots{waterlogged:false}"},
        {pos: [20, 6, 10], state: "minecraft:stone"},
        {pos: [20, 6, 11], state: "dustandash:cobblestone_with_moss"},
        {pos: [20, 6, 12], state: "dustandash:cobblestone_with_moss"},
        {pos: [20, 6, 14], state: "minecraft:grass"},
        {pos: [20, 6, 27], state: "minecraft:moss_block"},
        {pos: [20, 6, 28], state: "minecraft:moss_block"},
        {pos: [20, 6, 29], state: "minecraft:water{level:8}"},
        {pos: [20, 6, 30], state: "minecraft:moss_block"},
        {pos: [20, 6, 31], state: "dustandash:cobblestone_with_moss"},
        {pos: [20, 6, 32], state: "minecraft:stone"},
        {pos: [21, 6, 10], state: "minecraft:cobblestone"},
        {pos: [21, 6, 11], state: "dustandash:cobblestone_with_moss"},
        {pos: [21, 6, 12], state: "dustandash:cobblestone_with_moss"},
        {pos: [21, 6, 30], state: "minecraft:moss_block"},
        {pos: [21, 6, 31], state: "dustandash:cobblestone_with_moss"},
        {pos: [21, 6, 32], state: "minecraft:cobblestone"},
        {pos: [21, 6, 33], state: "minecraft:stone"},
        {pos: [22, 6, 10], state: "minecraft:stone"},
        {pos: [22, 6, 11], state: "dustandash:cobblestone_with_moss"},
        {pos: [22, 6, 12], state: "dustandash:cobblestone_with_moss"},
        {pos: [22, 6, 13], state: "minecraft:grass"},
        {pos: [22, 6, 30], state: "minecraft:moss_block"},
        {pos: [22, 6, 31], state: "dustandash:cobblestone_with_moss"},
        {pos: [22, 6, 32], state: "dustandash:cobblestone_with_moss"},
        {pos: [22, 6, 33], state: "minecraft:stone"},
        {pos: [23, 6, 10], state: "minecraft:cobblestone"},
        {pos: [23, 6, 11], state: "dustandash:cobblestone_with_moss"},
        {pos: [23, 6, 12], state: "dustandash:cobblestone_with_moss"},
        {pos: [23, 6, 13], state: "minecraft:grass"},
        {pos: [23, 6, 14], state: "minecraft:tall_grass{half:upper}"},
        {pos: [23, 6, 29], state: "minecraft:hay_block{axis:y}"},
        {pos: [23, 6, 30], state: "dustandash:cobblestone_with_moss"},
        {pos: [23, 6, 31], state: "dustandash:cobblestone_with_moss"},
        {pos: [23, 6, 32], state: "dustandash:cobblestone_with_moss"},
        {pos: [23, 6, 33], state: "minecraft:stone"},
        {pos: [23, 6, 34], state: "minecraft:stone"},
        {pos: [23, 6, 35], state: "minecraft:hanging_roots{waterlogged:false}"},
        {pos: [24, 6, 9], state: "minecraft:moss_block"},
        {pos: [24, 6, 10], state: "minecraft:stone"},
        {pos: [24, 6, 11], state: "dustandash:cobblestone_with_moss"},
        {pos: [24, 6, 12], state: "dustandash:cobblestone_with_moss"},
        {pos: [24, 6, 14], state: "minecraft:grass"},
        {pos: [24, 6, 19], state: "minecraft:lantern{hanging:true,waterlogged:false}"},
        {pos: [24, 6, 29], state: "minecraft:hay_block{axis:z}"},
        {pos: [24, 6, 30], state: "minecraft:hay_block{axis:x}"},
        {pos: [24, 6, 31], state: "minecraft:moss_block"},
        {pos: [24, 6, 32], state: "dustandash:cobblestone_with_moss"},
        {pos: [24, 6, 33], state: "dustandash:cobblestone_with_moss"},
        {pos: [24, 6, 34], state: "minecraft:cobblestone"},
        {pos: [25, 6, 9], state: "minecraft:moss_block"},
        {pos: [25, 6, 10], state: "dustandash:cobblestone_with_moss"},
        {pos: [25, 6, 11], state: "dustandash:cobblestone_with_moss"},
        {pos: [25, 6, 12], state: "dustandash:cobblestone_with_moss"},
        {pos: [25, 6, 13], state: "minecraft:grass"},
        {pos: [25, 6, 22], state: "quark:azalea_fence{east:true,north:false,south:false,waterlogged:false,west:false}"},
        {pos: [25, 6, 30], state: "minecraft:hay_block{axis:y}"},
        {pos: [25, 6, 31], state: "minecraft:moss_block"},
        {pos: [25, 6, 32], state: "dustandash:cobblestone_with_moss"},
        {pos: [25, 6, 33], state: "dustandash:cobblestone_with_moss"},
        {pos: [25, 6, 34], state: "minecraft:stone"},
        {pos: [26, 6, 10], state: "minecraft:cobblestone"},
        {pos: [26, 6, 11], state: "dustandash:cobblestone_with_moss"},
        {pos: [26, 6, 12], state: "dustandash:cobblestone_with_moss"},
        {pos: [26, 6, 15], state: "minecraft:moss_carpet"},
        {pos: [26, 6, 22], state: "quark:azalea_fence{east:false,north:false,south:false,waterlogged:false,west:true}"},
        {pos: [26, 6, 30], state: "minecraft:hay_block{axis:z}"},
        {pos: [26, 6, 31], state: "dustandash:cobblestone_with_moss"},
        {pos: [26, 6, 32], state: "dustandash:cobblestone_with_moss"},
        {pos: [26, 6, 33], state: "dustandash:cobblestone_with_moss"},
        {pos: [26, 6, 34], state: "minecraft:cobblestone"},
        {pos: [26, 6, 35], state: "minecraft:hanging_roots{waterlogged:false}"},
        {pos: [27, 6, 10], state: "minecraft:moss_block"},
        {pos: [27, 6, 11], state: "minecraft:stone"},
        {pos: [27, 6, 12], state: "dustandash:cobblestone_with_moss"},
        {pos: [27, 6, 13], state: "dustandash:cobblestone_with_moss"},
        {pos: [27, 6, 19], state: "quark:azalea_fence{east:false,north:false,south:false,waterlogged:false,west:false}"},
        {pos: [27, 6, 31], state: "dustandash:cobblestone_with_moss"},
        {pos: [27, 6, 32], state: "dustandash:cobblestone_with_moss"},
        {pos: [27, 6, 33], state: "dustandash:cobblestone_with_moss"},
        {pos: [27, 6, 34], state: "minecraft:stone"},
        {pos: [27, 6, 35], state: "minecraft:stone"},
        {pos: [28, 6, 11], state: "minecraft:cobblestone"},
        {pos: [28, 6, 12], state: "dustandash:cobblestone_with_moss"},
        {pos: [28, 6, 13], state: "dustandash:cobblestone_with_moss"},
        {pos: [28, 6, 32], state: "dustandash:cobblestone_with_moss"},
        {pos: [28, 6, 33], state: "dustandash:cobblestone_with_moss"},
        {pos: [28, 6, 34], state: "dustandash:cobblestone_with_moss"},
        {pos: [28, 6, 35], state: "minecraft:cobblestone"},
        {pos: [29, 6, 12], state: "minecraft:stone"},
        {pos: [29, 6, 13], state: "dustandash:cobblestone_with_moss"},
        {pos: [29, 6, 32], state: "dustandash:cobblestone_with_moss"},
        {pos: [29, 6, 33], state: "dustandash:cobblestone_with_moss"},
        {pos: [29, 6, 34], state: "dustandash:cobblestone_with_moss"},
        {pos: [29, 6, 35], state: "minecraft:stone"},
        {pos: [30, 6, 12], state: "minecraft:cobblestone"},
        {pos: [30, 6, 13], state: "dustandash:cobblestone_with_moss"},
        {pos: [30, 6, 14], state: "dustandash:cobblestone_with_moss"},
        {pos: [30, 6, 32], state: "dustandash:cobblestone_with_moss"},
        {pos: [30, 6, 33], state: "dustandash:cobblestone_with_moss"},
        {pos: [30, 6, 34], state: "dustandash:cobblestone_with_moss"},
        {pos: [30, 6, 35], state: "dustandash:cobblestone_with_moss"},
        {pos: [30, 6, 36], state: "minecraft:stone"},
        {pos: [31, 6, 12], state: "minecraft:stone"},
        {pos: [31, 6, 13], state: "dustandash:cobblestone_with_moss"},
        {pos: [31, 6, 14], state: "dustandash:cobblestone_with_moss"},
        {pos: [31, 6, 15], state: "dustandash:cobblestone_with_moss"},
        {pos: [31, 6, 32], state: "dustandash:cobblestone_with_moss"},
        {pos: [31, 6, 33], state: "dustandash:cobblestone_with_moss"},
        {pos: [31, 6, 34], state: "dustandash:cobblestone_with_moss"},
        {pos: [31, 6, 35], state: "dustandash:cobblestone_with_moss"},
        {pos: [31, 6, 36], state: "dustandash:cobblestone_with_moss"},
        {pos: [32, 6, 13], state: "minecraft:moss_block"},
        {pos: [32, 6, 14], state: "minecraft:stone"},
        {pos: [32, 6, 15], state: "dustandash:cobblestone_with_moss"},
        {pos: [32, 6, 16], state: "dustandash:cobblestone_with_moss"},
        {pos: [32, 6, 32], state: "dustandash:cobblestone_with_moss"},
        {pos: [32, 6, 33], state: "dustandash:cobblestone_with_moss"},
        {pos: [32, 6, 34], state: "dustandash:cobblestone_with_moss"},
        {pos: [32, 6, 35], state: "dustandash:cobblestone_with_moss"},
        {pos: [32, 6, 36], state: "minecraft:stone"},
        {pos: [33, 6, 14], state: "minecraft:stone"},
        {pos: [33, 6, 15], state: "minecraft:cobblestone"},
        {pos: [33, 6, 16], state: "dustandash:cobblestone_with_moss"},
        {pos: [33, 6, 17], state: "dustandash:cobblestone_with_moss"},
        {pos: [33, 6, 23], state: "minecraft:grass"},
        {pos: [33, 6, 31], state: "dustandash:cobblestone_with_moss"},
        {pos: [33, 6, 32], state: "dustandash:cobblestone_with_moss"},
        {pos: [33, 6, 33], state: "dustandash:cobblestone_with_moss"},
        {pos: [33, 6, 34], state: "dustandash:cobblestone_with_moss"},
        {pos: [33, 6, 35], state: "minecraft:cobblestone"},
        {pos: [33, 6, 36], state: "minecraft:moss_block"},
        {pos: [34, 6, 14], state: "minecraft:stone"},
        {pos: [34, 6, 15], state: "minecraft:stone"},
        {pos: [34, 6, 16], state: "dustandash:cobblestone_with_moss"},
        {pos: [34, 6, 17], state: "dustandash:cobblestone_with_moss"},
        {pos: [34, 6, 18], state: "dustandash:cobblestone_with_moss"},
        {pos: [34, 6, 24], state: "minecraft:grass"},
        {pos: [34, 6, 31], state: "dustandash:cobblestone_with_moss"},
        {pos: [34, 6, 32], state: "dustandash:cobblestone_with_moss"},
        {pos: [34, 6, 33], state: "dustandash:cobblestone_with_moss"},
        {pos: [34, 6, 34], state: "dustandash:cobblestone_with_moss"},
        {pos: [34, 6, 35], state: "minecraft:stone"},
        {pos: [35, 6, 15], state: "minecraft:stone"},
        {pos: [35, 6, 16], state: "minecraft:cobblestone"},
        {pos: [35, 6, 17], state: "dustandash:cobblestone_with_moss"},
        {pos: [35, 6, 18], state: "dustandash:cobblestone_with_moss"},
        {pos: [35, 6, 24], state: "minecraft:grass"},
        {pos: [35, 6, 25], state: "minecraft:moss_carpet"},
        {pos: [35, 6, 26], state: "minecraft:tall_grass{half:lower}"},
        {pos: [35, 6, 30], state: "dustandash:cobblestone_with_moss"},
        {pos: [35, 6, 31], state: "dustandash:cobblestone_with_moss"},
        {pos: [35, 6, 32], state: "dustandash:cobblestone_with_moss"},
        {pos: [35, 6, 33], state: "dustandash:cobblestone_with_moss"},
        {pos: [35, 6, 34], state: "minecraft:stone"},
        {pos: [35, 6, 36], state: "minecraft:moss_block"},
        {pos: [36, 6, 16], state: "minecraft:stone"},
        {pos: [36, 6, 17], state: "minecraft:stone"},
        {pos: [36, 6, 18], state: "dustandash:cobblestone_with_moss"},
        {pos: [36, 6, 19], state: "dustandash:cobblestone_with_moss"},
        {pos: [36, 6, 28], state: "dustandash:cobblestone_with_moss"},
        {pos: [36, 6, 29], state: "dustandash:cobblestone_with_moss"},
        {pos: [36, 6, 30], state: "dustandash:cobblestone_with_moss"},
        {pos: [36, 6, 31], state: "dustandash:cobblestone_with_moss"},
        {pos: [36, 6, 32], state: "dustandash:cobblestone_with_moss"},
        {pos: [36, 6, 33], state: "minecraft:cobblestone"},
        {pos: [37, 6, 16], state: "minecraft:moss_block"},
        {pos: [37, 6, 17], state: "minecraft:cobblestone"},
        {pos: [37, 6, 18], state: "dustandash:cobblestone_with_moss"},
        {pos: [37, 6, 19], state: "dustandash:cobblestone_with_moss"},
        {pos: [37, 6, 20], state: "dustandash:cobblestone_with_moss"},
        {pos: [37, 6, 25], state: "dustandash:cobblestone_with_moss"},
        {pos: [37, 6, 26], state: "dustandash:cobblestone_with_moss"},
        {pos: [37, 6, 27], state: "dustandash:cobblestone_with_moss"},
        {pos: [37, 6, 28], state: "dustandash:cobblestone_with_moss"},
        {pos: [37, 6, 29], state: "dustandash:cobblestone_with_moss"},
        {pos: [37, 6, 30], state: "dustandash:cobblestone_with_moss"},
        {pos: [37, 6, 31], state: "dustandash:cobblestone_with_moss"},
        {pos: [37, 6, 32], state: "dustandash:cobblestone_with_moss"},
        {pos: [37, 6, 33], state: "minecraft:cobblestone"},
        {pos: [38, 6, 18], state: "minecraft:stone"},
        {pos: [38, 6, 19], state: "minecraft:cobblestone"},
        {pos: [38, 6, 20], state: "dustandash:cobblestone_with_moss"},
        {pos: [38, 6, 21], state: "dustandash:cobblestone_with_moss"},
        {pos: [38, 6, 22], state: "dustandash:cobblestone_with_moss"},
        {pos: [38, 6, 23], state: "dustandash:cobblestone_with_moss"},
        {pos: [38, 6, 24], state: "dustandash:cobblestone_with_moss"},
        {pos: [38, 6, 25], state: "dustandash:cobblestone_with_moss"},
        {pos: [38, 6, 26], state: "dustandash:cobblestone_with_moss"},
        {pos: [38, 6, 27], state: "dustandash:cobblestone_with_moss"},
        {pos: [38, 6, 28], state: "dustandash:cobblestone_with_moss"},
        {pos: [38, 6, 29], state: "dustandash:cobblestone_with_moss"},
        {pos: [38, 6, 30], state: "dustandash:cobblestone_with_moss"},
        {pos: [38, 6, 31], state: "minecraft:cobblestone"},
        {pos: [38, 6, 32], state: "minecraft:stone"},
        {pos: [39, 6, 18], state: "minecraft:stone"},
        {pos: [39, 6, 19], state: "minecraft:moss_block"},
        {pos: [39, 6, 20], state: "minecraft:stone"},
        {pos: [39, 6, 21], state: "minecraft:stone"},
        {pos: [39, 6, 22], state: "minecraft:cobblestone"},
        {pos: [39, 6, 23], state: "dustandash:cobblestone_with_moss"},
        {pos: [39, 6, 24], state: "dustandash:cobblestone_with_moss"},
        {pos: [39, 6, 25], state: "dustandash:cobblestone_with_moss"},
        {pos: [39, 6, 26], state: "dustandash:cobblestone_with_moss"},
        {pos: [39, 6, 27], state: "dustandash:cobblestone_with_moss"},
        {pos: [39, 6, 28], state: "dustandash:cobblestone_with_moss"},
        {pos: [39, 6, 29], state: "dustandash:cobblestone_with_moss"},
        {pos: [39, 6, 30], state: "dustandash:cobblestone_with_moss"},
        {pos: [39, 6, 31], state: "minecraft:stone"},
        {pos: [39, 6, 32], state: "minecraft:moss_block"},
        {pos: [40, 6, 20], state: "minecraft:stone"},
        {pos: [40, 6, 22], state: "minecraft:moss_block"},
        {pos: [40, 6, 23], state: "dustandash:cobblestone_with_moss"},
        {pos: [40, 6, 24], state: "dustandash:cobblestone_with_moss"},
        {pos: [40, 6, 25], state: "minecraft:stone"},
        {pos: [40, 6, 26], state: "minecraft:cobblestone"},
        {pos: [40, 6, 27], state: "minecraft:stone"},
        {pos: [40, 6, 29], state: "minecraft:cobblestone"},
        {pos: [40, 6, 30], state: "minecraft:stone"},
        {pos: [41, 6, 23], state: "minecraft:moss_block"},
        {pos: [41, 6, 24], state: "minecraft:cobblestone"},
        {pos: [41, 6, 25], state: "minecraft:moss_block"},
        {pos: [41, 6, 27], state: "minecraft:moss_block"},
        {pos: [11, 7, 15], state: "minecraft:cobblestone"},
        {pos: [12, 7, 13], state: "minecraft:cobblestone"},
        {pos: [12, 7, 14], state: "minecraft:cobblestone"},
        {pos: [12, 7, 15], state: "minecraft:cobblestone"},
        {pos: [12, 7, 16], state: "dustandash:cobblestone_with_moss"},
        {pos: [12, 7, 17], state: "minecraft:cobblestone"},
        {pos: [12, 7, 18], state: "minecraft:cobblestone"},
        {pos: [12, 7, 19], state: "minecraft:cobblestone"},
        {pos: [12, 7, 21], state: "minecraft:cobblestone"},
        {pos: [13, 7, 10], state: "minecraft:cobblestone"},
        {pos: [13, 7, 11], state: "minecraft:cobblestone"},
        {pos: [13, 7, 12], state: "minecraft:cobblestone"},
        {pos: [13, 7, 13], state: "dustandash:cobblestone_with_moss"},
        {pos: [13, 7, 14], state: "minecraft:cobblestone"},
        {pos: [13, 7, 15], state: "minecraft:cobblestone"},
        {pos: [13, 7, 16], state: "minecraft:stone"},
        {pos: [13, 7, 17], state: "minecraft:stone"},
        {pos: [13, 7, 18], state: "minecraft:stone"},
        {pos: [13, 7, 19], state: "minecraft:cobblestone"},
        {pos: [13, 7, 20], state: "dustandash:cobblestone_with_moss"},
        {pos: [13, 7, 21], state: "minecraft:cobblestone"},
        {pos: [13, 7, 22], state: "minecraft:cobblestone"},
        {pos: [13, 7, 23], state: "minecraft:cobblestone"},
        {pos: [13, 7, 24], state: "dustandash:cobblestone_with_moss"},
        {pos: [13, 7, 26], state: "minecraft:cobblestone"},
        {pos: [14, 7, 9], state: "minecraft:cobblestone"},
        {pos: [14, 7, 10], state: "dustandash:cobblestone_with_moss"},
        {pos: [14, 7, 11], state: "minecraft:cobblestone"},
        {pos: [14, 7, 12], state: "minecraft:stone"},
        {pos: [14, 7, 13], state: "minecraft:cobblestone"},
        {pos: [14, 7, 14], state: "minecraft:stone"},
        {pos: [14, 7, 15], state: "minecraft:stone"},
        {pos: [14, 7, 16], state: "minecraft:stone"},
        {pos: [14, 7, 17], state: "minecraft:cobblestone"},
        {pos: [14, 7, 18], state: "minecraft:cobblestone"},
        {pos: [14, 7, 19], state: "dustandash:cobblestone_with_moss"},
        {pos: [14, 7, 20], state: "minecraft:stone"},
        {pos: [14, 7, 21], state: "minecraft:stone"},
        {pos: [14, 7, 22], state: "minecraft:cobblestone"},
        {pos: [14, 7, 23], state: "dustandash:cobblestone_with_moss"},
        {pos: [14, 7, 24], state: "minecraft:moss_block"},
        {pos: [14, 7, 25], state: "minecraft:clay"},
        {pos: [14, 7, 26], state: "minecraft:cobblestone"},
        {pos: [14, 7, 27], state: "minecraft:cobblestone"},
        {pos: [14, 7, 28], state: "minecraft:cobblestone"},
        {pos: [14, 7, 29], state: "dustandash:cobblestone_with_moss"},
        {pos: [15, 7, 9], state: "minecraft:cobblestone"},
        {pos: [15, 7, 10], state: "minecraft:stone"},
        {pos: [15, 7, 11], state: "minecraft:cobblestone"},
        {pos: [15, 7, 12], state: "minecraft:stone"},
        {pos: [15, 7, 13], state: "minecraft:cobblestone"},
        {pos: [15, 7, 14], state: "minecraft:cobblestone"},
        {pos: [15, 7, 15], state: "minecraft:cobblestone"},
        {pos: [15, 7, 16], state: "minecraft:clay"},
        {pos: [15, 7, 17], state: "minecraft:stone"},
        {pos: [15, 7, 18], state: "dustandash:cobblestone_with_moss"},
        {pos: [15, 7, 19], state: "dustandash:cobblestone_with_moss"},
        {pos: [15, 7, 20], state: "minecraft:stone"},
        {pos: [15, 7, 21], state: "minecraft:cobblestone"},
        {pos: [15, 7, 22], state: "minecraft:moss_block"},
        {pos: [15, 7, 23], state: "minecraft:moss_block"},
        {pos: [15, 7, 24], state: "minecraft:cobblestone"},
        {pos: [15, 7, 25], state: "minecraft:moss_block"},
        {pos: [15, 7, 26], state: "minecraft:cobblestone"},
        {pos: [15, 7, 27], state: "minecraft:stone"},
        {pos: [15, 7, 28], state: "minecraft:cobblestone"},
        {pos: [15, 7, 29], state: "minecraft:cobblestone"},
        {pos: [15, 7, 30], state: "minecraft:stone"},
        {pos: [16, 7, 9], state: "dustandash:cobblestone_with_moss"},
        {pos: [16, 7, 10], state: "minecraft:cobblestone"},
        {pos: [16, 7, 11], state: "minecraft:cobblestone"},
        {pos: [16, 7, 12], state: "minecraft:cobblestone"},
        {pos: [16, 7, 13], state: "minecraft:clay"},
        {pos: [16, 7, 14], state: "minecraft:cobblestone"},
        {pos: [16, 7, 15], state: "minecraft:moss_block"},
        {pos: [16, 7, 16], state: "minecraft:cobblestone"},
        {pos: [16, 7, 17], state: "minecraft:cobblestone"},
        {pos: [16, 7, 18], state: "minecraft:moss_block"},
        {pos: [16, 7, 19], state: "minecraft:stone"},
        {pos: [16, 7, 20], state: "minecraft:cobblestone"},
        {pos: [16, 7, 21], state: "minecraft:tall_grass{half:lower}"},
        {pos: [16, 7, 23], state: "minecraft:flowering_azalea"},
        {pos: [16, 7, 24], state: "minecraft:moss_carpet"},
        {pos: [16, 7, 25], state: "minecraft:grass"},
        {pos: [16, 7, 26], state: "minecraft:cobblestone"},
        {pos: [16, 7, 27], state: "dustandash:cobblestone_with_moss"},
        {pos: [16, 7, 28], state: "dustandash:cobblestone_with_moss"},
        {pos: [16, 7, 29], state: "minecraft:cobblestone"},
        {pos: [16, 7, 30], state: "minecraft:cobblestone"},
        {pos: [16, 7, 31], state: "minecraft:cobblestone"},
        {pos: [16, 7, 32], state: "minecraft:cobblestone"},
        {pos: [16, 7, 33], state: "dustandash:cobblestone_with_moss"},
        {pos: [17, 7, 9], state: "minecraft:cobblestone"},
        {pos: [17, 7, 10], state: "minecraft:cobblestone"},
        {pos: [17, 7, 11], state: "minecraft:cobblestone"},
        {pos: [17, 7, 12], state: "minecraft:stone"},
        {pos: [17, 7, 13], state: "minecraft:cobblestone"},
        {pos: [17, 7, 14], state: "minecraft:cobblestone"},
        {pos: [17, 7, 15], state: "minecraft:cobblestone"},
        {pos: [17, 7, 16], state: "minecraft:flowering_azalea"},
        {pos: [17, 7, 27], state: "minecraft:tall_grass{half:upper}"},
        {pos: [17, 7, 28], state: "minecraft:cobblestone"},
        {pos: [17, 7, 29], state: "minecraft:clay"},
        {pos: [17, 7, 30], state: "dustandash:cobblestone_with_moss"},
        {pos: [17, 7, 31], state: "minecraft:cobblestone"},
        {pos: [17, 7, 32], state: "minecraft:cobblestone"},
        {pos: [17, 7, 33], state: "minecraft:cobblestone"},
        {pos: [17, 7, 34], state: "minecraft:cobblestone"},
        {pos: [18, 7, 8], state: "minecraft:cobblestone"},
        {pos: [18, 7, 9], state: "minecraft:cobblestone"},
        {pos: [18, 7, 10], state: "minecraft:cobblestone"},
        {pos: [18, 7, 11], state: "minecraft:stone"},
        {pos: [18, 7, 12], state: "minecraft:cobblestone"},
        {pos: [18, 7, 13], state: "minecraft:cobblestone"},
        {pos: [18, 7, 14], state: "minecraft:grass"},
        {pos: [18, 7, 29], state: "minecraft:moss_block"},
        {pos: [18, 7, 30], state: "minecraft:cobblestone"},
        {pos: [18, 7, 31], state: "minecraft:moss_block"},
        {pos: [18, 7, 32], state: "minecraft:moss_block"},
        {pos: [18, 7, 33], state: "minecraft:cobblestone"},
        {pos: [18, 7, 34], state: "minecraft:cobblestone"},
        {pos: [18, 7, 35], state: "minecraft:cobblestone"},
        {pos: [19, 7, 8], state: "minecraft:cobblestone"},
        {pos: [19, 7, 9], state: "minecraft:cobblestone"},
        {pos: [19, 7, 10], state: "minecraft:cobblestone"},
        {pos: [19, 7, 11], state: "minecraft:cobblestone"},
        {pos: [19, 7, 12], state: "minecraft:clay"},
        {pos: [19, 7, 14], state: "minecraft:tall_grass{half:upper}"},
        {pos: [19, 7, 29], state: "minecraft:dirt"},
        {pos: [19, 7, 30], state: "minecraft:moss_block"},
        {pos: [19, 7, 31], state: "dustandash:cobblestone_with_moss"},
        {pos: [19, 7, 32], state: "minecraft:moss_block"},
        {pos: [19, 7, 33], state: "dustandash:cobblestone_with_moss"},
        {pos: [19, 7, 34], state: "minecraft:cobblestone"},
        {pos: [19, 7, 35], state: "minecraft:cobblestone"},
        {pos: [20, 7, 8], state: "dustandash:cobblestone_with_moss"},
        {pos: [20, 7, 9], state: "minecraft:cobblestone"},
        {pos: [20, 7, 10], state: "minecraft:stone"},
        {pos: [20, 7, 11], state: "minecraft:cobblestone"},
        {pos: [20, 7, 12], state: "minecraft:cobblestone"},
        {pos: [20, 7, 29], state: "minecraft:water{level:1}"},
        {pos: [20, 7, 30], state: "minecraft:water{level:8}"},
        {pos: [20, 7, 31], state: "minecraft:moss_block"},
        {pos: [20, 7, 32], state: "minecraft:moss_block"},
        {pos: [20, 7, 33], state: "minecraft:moss_block"},
        {pos: [20, 7, 34], state: "minecraft:moss_block"},
        {pos: [20, 7, 35], state: "minecraft:cobblestone"},
        {pos: [21, 7, 7], state: "minecraft:cobblestone"},
        {pos: [21, 7, 8], state: "minecraft:cobblestone"},
        {pos: [21, 7, 9], state: "minecraft:stone"},
        {pos: [21, 7, 10], state: "minecraft:cobblestone"},
        {pos: [21, 7, 11], state: "dustandash:cobblestone_with_moss"},
        {pos: [21, 7, 31], state: "dustandash:cobblestone_with_moss"},
        {pos: [21, 7, 32], state: "minecraft:clay"},
        {pos: [21, 7, 33], state: "minecraft:moss_block"},
        {pos: [21, 7, 34], state: "minecraft:moss_block"},
        {pos: [21, 7, 35], state: "minecraft:cobblestone"},
        {pos: [22, 7, 7], state: "minecraft:cobblestone"},
        {pos: [22, 7, 8], state: "minecraft:cobblestone"},
        {pos: [22, 7, 9], state: "minecraft:cobblestone"},
        {pos: [22, 7, 10], state: "minecraft:cobblestone"},
        {pos: [22, 7, 11], state: "minecraft:cobblestone"},
        {pos: [22, 7, 31], state: "minecraft:moss_block"},
        {pos: [22, 7, 32], state: "minecraft:moss_block"},
        {pos: [22, 7, 33], state: "minecraft:moss_block"},
        {pos: [22, 7, 34], state: "minecraft:moss_block"},
        {pos: [22, 7, 35], state: "minecraft:cobblestone"},
        {pos: [22, 7, 36], state: "minecraft:cobblestone"},
        {pos: [23, 7, 7], state: "minecraft:cobblestone"},
        {pos: [23, 7, 8], state: "minecraft:cobblestone"},
        {pos: [23, 7, 9], state: "minecraft:stone"},
        {pos: [23, 7, 10], state: "dustandash:cobblestone_with_moss"},
        {pos: [23, 7, 11], state: "minecraft:clay"},
        {pos: [23, 7, 30], state: "minecraft:hay_block{axis:y}"},
        {pos: [23, 7, 31], state: "minecraft:moss_block"},
        {pos: [23, 7, 32], state: "minecraft:moss_block"},
        {pos: [23, 7, 33], state: "minecraft:moss_block"},
        {pos: [23, 7, 34], state: "minecraft:moss_block"},
        {pos: [23, 7, 35], state: "minecraft:cobblestone"},
        {pos: [23, 7, 36], state: "minecraft:cobblestone"},
        {pos: [24, 7, 7], state: "dustandash:cobblestone_with_moss"},
        {pos: [24, 7, 8], state: "minecraft:stone"},
        {pos: [24, 7, 9], state: "minecraft:cobblestone"},
        {pos: [24, 7, 10], state: "dustandash:cobblestone_with_moss"},
        {pos: [24, 7, 11], state: "minecraft:cobblestone"},
        {pos: [24, 7, 19], state: "quark:azalea_planks_slab{type:bottom,waterlogged:false}"},
        {pos: [24, 7, 20], state: "quark:azalea_planks_slab{type:bottom,waterlogged:false}"},
        {pos: [24, 7, 31], state: "minecraft:hay_block{axis:y}"},
        {pos: [24, 7, 32], state: "minecraft:moss_block"},
        {pos: [24, 7, 33], state: "minecraft:moss_block"},
        {pos: [24, 7, 34], state: "minecraft:cobblestone"},
        {pos: [24, 7, 35], state: "minecraft:moss_block"},
        {pos: [24, 7, 36], state: "dustandash:cobblestone_with_moss"},
        {pos: [25, 7, 7], state: "minecraft:cobblestone"},
        {pos: [25, 7, 8], state: "minecraft:cobblestone"},
        {pos: [25, 7, 9], state: "dustandash:cobblestone_with_moss"},
        {pos: [25, 7, 10], state: "minecraft:cobblestone"},
        {pos: [25, 7, 11], state: "minecraft:clay"},
        {pos: [25, 7, 18], state: "quark:azalea_planks_slab{type:bottom,waterlogged:false}"},
        {pos: [25, 7, 19], state: "quark:azalea_planks_slab{type:bottom,waterlogged:false}"},
        {pos: [25, 7, 20], state: "quark:azalea_planks_slab{type:bottom,waterlogged:false}"},
        {pos: [25, 7, 21], state: "quark:azalea_planks_slab{type:bottom,waterlogged:false}"},
        {pos: [25, 7, 22], state: "quark:azalea_planks_slab{type:bottom,waterlogged:false}"},
        {pos: [25, 7, 31], state: "minecraft:hay_block{axis:z}"},
        {pos: [25, 7, 32], state: "minecraft:moss_block"},
        {pos: [25, 7, 33], state: "minecraft:cobblestone"},
        {pos: [25, 7, 34], state: "minecraft:cobblestone"},
        {pos: [25, 7, 35], state: "minecraft:stone"},
        {pos: [25, 7, 36], state: "minecraft:cobblestone"},
        {pos: [26, 7, 8], state: "dustandash:cobblestone_with_moss"},
        {pos: [26, 7, 9], state: "minecraft:stone"},
        {pos: [26, 7, 10], state: "minecraft:cobblestone"},
        {pos: [26, 7, 11], state: "minecraft:cobblestone"},
        {pos: [26, 7, 18], state: "quark:azalea_planks_slab{type:bottom,waterlogged:false}"},
        {pos: [26, 7, 19], state: "quark:azalea_planks_slab{type:bottom,waterlogged:false}"},
        {pos: [26, 7, 20], state: "quark:azalea_planks_slab{type:bottom,waterlogged:false}"},
        {pos: [26, 7, 21], state: "quark:azalea_planks_slab{type:bottom,waterlogged:false}"},
        {pos: [26, 7, 22], state: "quark:azalea_planks_slab{type:bottom,waterlogged:false}"},
        {pos: [26, 7, 23], state: "quark:azalea_planks_slab{type:bottom,waterlogged:false}"},
        {pos: [26, 7, 32], state: "minecraft:cobblestone"},
        {pos: [26, 7, 33], state: "minecraft:clay"},
        {pos: [26, 7, 34], state: "minecraft:cobblestone"},
        {pos: [26, 7, 35], state: "minecraft:stone"},
        {pos: [26, 7, 36], state: "minecraft:cobblestone"},
        {pos: [27, 7, 9], state: "minecraft:cobblestone"},
        {pos: [27, 7, 10], state: "minecraft:stone"},
        {pos: [27, 7, 11], state: "dustandash:cobblestone_with_moss"},
        {pos: [27, 7, 12], state: "minecraft:cobblestone"},
        {pos: [27, 7, 18], state: "quark:azalea_planks_slab{type:top,waterlogged:false}"},
        {pos: [27, 7, 19], state: "quark:azalea_planks_slab{type:double,waterlogged:false}"},
        {pos: [27, 7, 20], state: "quark:azalea_planks_slab{type:double,waterlogged:false}"},
        {pos: [27, 7, 21], state: "quark:azalea_planks_slab{type:bottom,waterlogged:false}"},
        {pos: [27, 7, 22], state: "quark:azalea_planks_slab{type:bottom,waterlogged:false}"},
        {pos: [27, 7, 34], state: "minecraft:cobblestone"},
        {pos: [27, 7, 35], state: "minecraft:cobblestone"},
        {pos: [27, 7, 36], state: "minecraft:cobblestone"},
        {pos: [27, 7, 37], state: "dustandash:cobblestone_with_moss"},
        {pos: [28, 7, 10], state: "minecraft:cobblestone"},
        {pos: [28, 7, 11], state: "minecraft:stone"},
        {pos: [28, 7, 12], state: "minecraft:cobblestone"},
        {pos: [28, 7, 19], state: "quark:azalea_planks_slab{type:top,waterlogged:false}"},
        {pos: [28, 7, 20], state: "quark:azalea_planks_slab{type:top,waterlogged:false}"},
        {pos: [28, 7, 21], state: "quark:azalea_planks_slab{type:bottom,waterlogged:false}"},
        {pos: [28, 7, 33], state: "minecraft:cobblestone"},
        {pos: [28, 7, 34], state: "minecraft:stone"},
        {pos: [28, 7, 35], state: "minecraft:cobblestone"},
        {pos: [28, 7, 36], state: "minecraft:cobblestone"},
        {pos: [28, 7, 37], state: "minecraft:cobblestone"},
        {pos: [29, 7, 10], state: "minecraft:cobblestone"},
        {pos: [29, 7, 11], state: "minecraft:stone"},
        {pos: [29, 7, 12], state: "minecraft:cobblestone"},
        {pos: [29, 7, 13], state: "minecraft:clay"},
        {pos: [29, 7, 33], state: "minecraft:cobblestone"},
        {pos: [29, 7, 34], state: "minecraft:stone"},
        {pos: [29, 7, 35], state: "minecraft:cobblestone"},
        {pos: [29, 7, 36], state: "minecraft:cobblestone"},
        {pos: [30, 7, 10], state: "minecraft:cobblestone"},
        {pos: [30, 7, 11], state: "minecraft:cobblestone"},
        {pos: [30, 7, 12], state: "minecraft:stone"},
        {pos: [30, 7, 13], state: "minecraft:cobblestone"},
        {pos: [30, 7, 33], state: "minecraft:cobblestone"},
        {pos: [30, 7, 34], state: "minecraft:cobblestone"},
        {pos: [30, 7, 35], state: "dustandash:cobblestone_with_moss"},
        {pos: [30, 7, 36], state: "minecraft:stone"},
        {pos: [31, 7, 11], state: "dustandash:cobblestone_with_moss"},
        {pos: [31, 7, 12], state: "minecraft:stone"},
        {pos: [31, 7, 13], state: "minecraft:cobblestone"},
        {pos: [31, 7, 14], state: "minecraft:cobblestone"},
        {pos: [31, 7, 33], state: "minecraft:clay"},
        {pos: [31, 7, 34], state: "dustandash:cobblestone_with_moss"},
        {pos: [31, 7, 35], state: "minecraft:cobblestone"},
        {pos: [31, 7, 36], state: "minecraft:cobblestone"},
        {pos: [31, 7, 37], state: "minecraft:moss_block"},
        {pos: [32, 7, 12], state: "minecraft:cobblestone"},
        {pos: [32, 7, 13], state: "minecraft:stone"},
        {pos: [32, 7, 14], state: "minecraft:cobblestone"},
        {pos: [32, 7, 15], state: "minecraft:cobblestone"},
        {pos: [32, 7, 32], state: "minecraft:cobblestone"},
        {pos: [32, 7, 33], state: "minecraft:cobblestone"},
        {pos: [32, 7, 34], state: "minecraft:cobblestone"},
        {pos: [32, 7, 35], state: "minecraft:cobblestone"},
        {pos: [32, 7, 36], state: "minecraft:cobblestone"},
        {pos: [32, 7, 37], state: "minecraft:moss_block"},
        {pos: [33, 7, 12], state: "minecraft:cobblestone"},
        {pos: [33, 7, 13], state: "minecraft:cobblestone"},
        {pos: [33, 7, 14], state: "minecraft:stone"},
        {pos: [33, 7, 15], state: "minecraft:cobblestone"},
        {pos: [33, 7, 16], state: "minecraft:clay"},
        {pos: [33, 7, 31], state: "minecraft:cobblestone"},
        {pos: [33, 7, 32], state: "minecraft:cobblestone"},
        {pos: [33, 7, 33], state: "minecraft:cobblestone"},
        {pos: [33, 7, 34], state: "minecraft:cobblestone"},
        {pos: [33, 7, 35], state: "minecraft:cobblestone"},
        {pos: [33, 7, 36], state: "minecraft:cobblestone"},
        {pos: [33, 7, 37], state: "minecraft:moss_block"},
        {pos: [34, 7, 13], state: "minecraft:cobblestone"},
        {pos: [34, 7, 14], state: "dustandash:cobblestone_with_moss"},
        {pos: [34, 7, 15], state: "minecraft:stone"},
        {pos: [34, 7, 16], state: "minecraft:cobblestone"},
        {pos: [34, 7, 17], state: "minecraft:cobblestone"},
        {pos: [34, 7, 31], state: "minecraft:cobblestone"},
        {pos: [34, 7, 32], state: "minecraft:clay"},
        {pos: [34, 7, 33], state: "dustandash:cobblestone_with_moss"},
        {pos: [34, 7, 34], state: "minecraft:cobblestone"},
        {pos: [34, 7, 35], state: "minecraft:cobblestone"},
        {pos: [34, 7, 36], state: "minecraft:cobblestone"},
        {pos: [35, 7, 13], state: "minecraft:cobblestone"},
        {pos: [35, 7, 14], state: "dustandash:cobblestone_with_moss"},
        {pos: [35, 7, 15], state: "minecraft:cobblestone"},
        {pos: [35, 7, 16], state: "minecraft:stone"},
        {pos: [35, 7, 17], state: "minecraft:clay"},
        {pos: [35, 7, 18], state: "minecraft:cobblestone"},
        {pos: [35, 7, 26], state: "minecraft:tall_grass{half:upper}"},
        {pos: [35, 7, 30], state: "minecraft:cobblestone"},
        {pos: [35, 7, 31], state: "minecraft:cobblestone"},
        {pos: [35, 7, 32], state: "minecraft:cobblestone"},
        {pos: [35, 7, 33], state: "minecraft:cobblestone"},
        {pos: [35, 7, 34], state: "minecraft:cobblestone"},
        {pos: [35, 7, 35], state: "minecraft:stone"},
        {pos: [35, 7, 36], state: "minecraft:cobblestone"},
        {pos: [36, 7, 13], state: "minecraft:cobblestone"},
        {pos: [36, 7, 14], state: "minecraft:cobblestone"},
        {pos: [36, 7, 15], state: "minecraft:cobblestone"},
        {pos: [36, 7, 16], state: "dustandash:cobblestone_with_moss"},
        {pos: [36, 7, 17], state: "minecraft:stone"},
        {pos: [36, 7, 18], state: "minecraft:cobblestone"},
        {pos: [36, 7, 29], state: "minecraft:cobblestone"},
        {pos: [36, 7, 30], state: "dustandash:cobblestone_with_moss"},
        {pos: [36, 7, 31], state: "minecraft:cobblestone"},
        {pos: [36, 7, 32], state: "minecraft:cobblestone"},
        {pos: [36, 7, 33], state: "minecraft:stone"},
        {pos: [36, 7, 34], state: "minecraft:cobblestone"},
        {pos: [36, 7, 35], state: "dustandash:cobblestone_with_moss"},
        {pos: [37, 7, 14], state: "minecraft:cobblestone"},
        {pos: [37, 7, 15], state: "dustandash:cobblestone_with_moss"},
        {pos: [37, 7, 16], state: "minecraft:stone"},
        {pos: [37, 7, 17], state: "minecraft:stone"},
        {pos: [37, 7, 18], state: "minecraft:stone"},
        {pos: [37, 7, 19], state: "minecraft:clay"},
        {pos: [37, 7, 20], state: "minecraft:cobblestone"},
        {pos: [37, 7, 26], state: "dustandash:cobblestone_with_moss"},
        {pos: [37, 7, 27], state: "minecraft:stone"},
        {pos: [37, 7, 28], state: "minecraft:cobblestone"},
        {pos: [37, 7, 29], state: "minecraft:cobblestone"},
        {pos: [37, 7, 30], state: "minecraft:clay"},
        {pos: [37, 7, 31], state: "dustandash:cobblestone_with_moss"},
        {pos: [37, 7, 32], state: "minecraft:stone"},
        {pos: [37, 7, 33], state: "minecraft:stone"},
        {pos: [37, 7, 34], state: "minecraft:cobblestone"},
        {pos: [37, 7, 35], state: "minecraft:cobblestone"},
        {pos: [38, 7, 14], state: "minecraft:cobblestone"},
        {pos: [38, 7, 15], state: "minecraft:cobblestone"},
        {pos: [38, 7, 16], state: "minecraft:cobblestone"},
        {pos: [38, 7, 17], state: "dustandash:cobblestone_with_moss"},
        {pos: [38, 7, 18], state: "minecraft:stone"},
        {pos: [38, 7, 19], state: "minecraft:cobblestone"},
        {pos: [38, 7, 20], state: "minecraft:cobblestone"},
        {pos: [38, 7, 21], state: "minecraft:cobblestone"},
        {pos: [38, 7, 22], state: "minecraft:cobblestone"},
        {pos: [38, 7, 23], state: "minecraft:clay"},
        {pos: [38, 7, 24], state: "dustandash:cobblestone_with_moss"},
        {pos: [38, 7, 25], state: "minecraft:stone"},
        {pos: [38, 7, 26], state: "minecraft:cobblestone"},
        {pos: [38, 7, 27], state: "dustandash:cobblestone_with_moss"},
        {pos: [38, 7, 28], state: "dustandash:cobblestone_with_moss"},
        {pos: [38, 7, 29], state: "minecraft:cobblestone"},
        {pos: [38, 7, 30], state: "minecraft:cobblestone"},
        {pos: [38, 7, 31], state: "minecraft:cobblestone"},
        {pos: [38, 7, 32], state: "dustandash:cobblestone_with_moss"},
        {pos: [38, 7, 33], state: "minecraft:cobblestone"},
        {pos: [38, 7, 34], state: "dustandash:cobblestone_with_moss"},
        {pos: [38, 7, 35], state: "minecraft:cobblestone"},
        {pos: [38, 7, 36], state: "minecraft:moss_block"},
        {pos: [39, 7, 15], state: "minecraft:cobblestone"},
        {pos: [39, 7, 16], state: "minecraft:cobblestone"},
        {pos: [39, 7, 17], state: "minecraft:cobblestone"},
        {pos: [39, 7, 18], state: "minecraft:cobblestone"},
        {pos: [39, 7, 19], state: "minecraft:cobblestone"},
        {pos: [39, 7, 20], state: "minecraft:stone"},
        {pos: [39, 7, 21], state: "minecraft:cobblestone"},
        {pos: [39, 7, 22], state: "dustandash:cobblestone_with_moss"},
        {pos: [39, 7, 23], state: "minecraft:cobblestone"},
        {pos: [39, 7, 24], state: "dustandash:cobblestone_with_moss"},
        {pos: [39, 7, 25], state: "minecraft:cobblestone"},
        {pos: [39, 7, 26], state: "dustandash:cobblestone_with_moss"},
        {pos: [39, 7, 27], state: "minecraft:cobblestone"},
        {pos: [39, 7, 28], state: "minecraft:stone"},
        {pos: [39, 7, 29], state: "minecraft:cobblestone"},
        {pos: [39, 7, 30], state: "minecraft:stone"},
        {pos: [39, 7, 31], state: "minecraft:cobblestone"},
        {pos: [39, 7, 32], state: "minecraft:cobblestone"},
        {pos: [39, 7, 33], state: "minecraft:cobblestone"},
        {pos: [39, 7, 34], state: "minecraft:cobblestone"},
        {pos: [40, 7, 16], state: "minecraft:cobblestone"},
        {pos: [40, 7, 17], state: "minecraft:cobblestone"},
        {pos: [40, 7, 18], state: "minecraft:cobblestone"},
        {pos: [40, 7, 19], state: "dustandash:cobblestone_with_moss"},
        {pos: [40, 7, 20], state: "minecraft:cobblestone"},
        {pos: [40, 7, 21], state: "minecraft:cobblestone"},
        {pos: [40, 7, 22], state: "minecraft:stone"},
        {pos: [40, 7, 23], state: "minecraft:cobblestone"},
        {pos: [40, 7, 24], state: "minecraft:cobblestone"},
        {pos: [40, 7, 25], state: "minecraft:cobblestone"},
        {pos: [40, 7, 26], state: "minecraft:cobblestone"},
        {pos: [40, 7, 27], state: "minecraft:cobblestone"},
        {pos: [40, 7, 28], state: "minecraft:cobblestone"},
        {pos: [40, 7, 29], state: "minecraft:cobblestone"},
        {pos: [40, 7, 30], state: "minecraft:cobblestone"},
        {pos: [40, 7, 31], state: "minecraft:cobblestone"},
        {pos: [40, 7, 32], state: "dustandash:cobblestone_with_moss"},
        {pos: [40, 7, 33], state: "minecraft:cobblestone"},
        {pos: [40, 7, 34], state: "minecraft:moss_block"},
        {pos: [41, 7, 18], state: "minecraft:stone"},
        {pos: [41, 7, 19], state: "minecraft:cobblestone"},
        {pos: [41, 7, 20], state: "minecraft:cobblestone"},
        {pos: [41, 7, 21], state: "minecraft:stone"},
        {pos: [41, 7, 22], state: "minecraft:stone"},
        {pos: [41, 7, 23], state: "minecraft:cobblestone"},
        {pos: [41, 7, 24], state: "minecraft:cobblestone"},
        {pos: [41, 7, 25], state: "minecraft:cobblestone"},
        {pos: [41, 7, 26], state: "dustandash:cobblestone_with_moss"},
        {pos: [41, 7, 27], state: "minecraft:stone"},
        {pos: [41, 7, 28], state: "minecraft:moss_block"},
        {pos: [41, 7, 29], state: "minecraft:moss_block"},
        {pos: [41, 7, 30], state: "minecraft:moss_block"},
        {pos: [42, 7, 21], state: "minecraft:stone"},
        {pos: [42, 7, 24], state: "minecraft:stone"},
        {pos: [42, 7, 25], state: "minecraft:stone"},
        {pos: [42, 7, 26], state: "minecraft:moss_block"},
        {pos: [42, 7, 27], state: "minecraft:moss_block"},
        {pos: [10, 8, 18], state: "minecraft:clay"},
        {pos: [10, 8, 19], state: "minecraft:cobblestone"},
        {pos: [10, 8, 20], state: "minecraft:clay"},
        {pos: [11, 8, 12], state: "minecraft:clay"},
        {pos: [11, 8, 13], state: "minecraft:clay"},
        {pos: [11, 8, 14], state: "minecraft:clay"},
        {pos: [11, 8, 15], state: "minecraft:cobblestone"},
        {pos: [11, 8, 16], state: "minecraft:clay"},
        {pos: [11, 8, 17], state: "minecraft:clay"},
        {pos: [11, 8, 18], state: "minecraft:clay"},
        {pos: [11, 8, 19], state: "minecraft:clay"},
        {pos: [11, 8, 20], state: "minecraft:clay"},
        {pos: [11, 8, 21], state: "minecraft:clay"},
        {pos: [11, 8, 22], state: "minecraft:clay"},
        {pos: [11, 8, 23], state: "minecraft:clay"},
        {pos: [11, 8, 24], state: "minecraft:clay"},
        {pos: [11, 8, 25], state: "minecraft:clay"},
        {pos: [11, 8, 26], state: "minecraft:cobblestone"},
        {pos: [12, 8, 7], state: "minecraft:clay"},
        {pos: [12, 8, 8], state: "minecraft:clay"},
        {pos: [12, 8, 9], state: "minecraft:cobblestone"},
        {pos: [12, 8, 10], state: "minecraft:clay"},
        {pos: [12, 8, 11], state: "minecraft:clay"},
        {pos: [12, 8, 12], state: "minecraft:clay"},
        {pos: [12, 8, 13], state: "minecraft:cobblestone"},
        {pos: [12, 8, 14], state: "minecraft:clay"},
        {pos: [12, 8, 15], state: "minecraft:clay"},
        {pos: [12, 8, 16], state: "minecraft:clay"},
        {pos: [12, 8, 17], state: "minecraft:clay"},
        {pos: [12, 8, 18], state: "minecraft:stone"},
        {pos: [12, 8, 19], state: "minecraft:clay"},
        {pos: [12, 8, 20], state: "minecraft:clay"},
        {pos: [12, 8, 21], state: "minecraft:clay"},
        {pos: [12, 8, 22], state: "minecraft:clay"},
        {pos: [12, 8, 23], state: "minecraft:clay"},
        {pos: [12, 8, 24], state: "minecraft:clay"},
        {pos: [12, 8, 25], state: "minecraft:clay"},
        {pos: [12, 8, 26], state: "minecraft:clay"},
        {pos: [12, 8, 27], state: "minecraft:clay"},
        {pos: [12, 8, 28], state: "minecraft:clay"},
        {pos: [12, 8, 29], state: "minecraft:clay"},
        {pos: [12, 8, 30], state: "minecraft:clay"},
        {pos: [12, 8, 31], state: "minecraft:cobblestone"},
        {pos: [12, 8, 32], state: "minecraft:clay"},
        {pos: [12, 8, 33], state: "minecraft:clay"},
        {pos: [13, 8, 6], state: "minecraft:clay"},
        {pos: [13, 8, 7], state: "minecraft:cobblestone"},
        {pos: [13, 8, 8], state: "minecraft:clay"},
        {pos: [13, 8, 9], state: "minecraft:clay"},
        {pos: [13, 8, 10], state: "minecraft:clay"},
        {pos: [13, 8, 11], state: "minecraft:cobblestone"},
        {pos: [13, 8, 12], state: "minecraft:clay"},
        {pos: [13, 8, 13], state: "minecraft:stone"},
        {pos: [13, 8, 14], state: "minecraft:clay"},
        {pos: [13, 8, 15], state: "minecraft:clay"},
        {pos: [13, 8, 16], state: "minecraft:stone"},
        {pos: [13, 8, 17], state: "minecraft:clay"},
        {pos: [13, 8, 18], state: "minecraft:clay"},
        {pos: [13, 8, 19], state: "minecraft:clay"},
        {pos: [13, 8, 20], state: "dustandash:cobblestone_with_moss"},
        {pos: [13, 8, 21], state: "minecraft:stone"},
        {pos: [13, 8, 22], state: "minecraft:clay"},
        {pos: [13, 8, 23], state: "minecraft:moss_block"},
        {pos: [13, 8, 24], state: "minecraft:clay"},
        {pos: [13, 8, 25], state: "minecraft:clay"},
        {pos: [13, 8, 26], state: "minecraft:moss_block"},
        {pos: [13, 8, 27], state: "minecraft:clay"},
        {pos: [13, 8, 28], state: "minecraft:clay"},
        {pos: [13, 8, 29], state: "minecraft:clay"},
        {pos: [13, 8, 30], state: "minecraft:clay"},
        {pos: [13, 8, 31], state: "minecraft:clay"},
        {pos: [13, 8, 32], state: "minecraft:clay"},
        {pos: [13, 8, 33], state: "minecraft:clay"},
        {pos: [13, 8, 34], state: "minecraft:clay"},
        {pos: [14, 8, 6], state: "minecraft:clay"},
        {pos: [14, 8, 7], state: "minecraft:clay"},
        {pos: [14, 8, 8], state: "minecraft:clay"},
        {pos: [14, 8, 9], state: "minecraft:stone"},
        {pos: [14, 8, 10], state: "minecraft:clay"},
        {pos: [14, 8, 11], state: "minecraft:clay"},
        {pos: [14, 8, 12], state: "minecraft:clay"},
        {pos: [14, 8, 21], state: "minecraft:moss_carpet"},
        {pos: [14, 8, 26], state: "minecraft:clay"},
        {pos: [14, 8, 27], state: "minecraft:clay"},
        {pos: [14, 8, 29], state: "minecraft:clay"},
        {pos: [14, 8, 30], state: "minecraft:clay"},
        {pos: [14, 8, 31], state: "minecraft:stone"},
        {pos: [14, 8, 32], state: "minecraft:clay"},
        {pos: [14, 8, 33], state: "minecraft:clay"},
        {pos: [14, 8, 34], state: "minecraft:clay"},
        {pos: [14, 8, 35], state: "minecraft:clay"},
        {pos: [15, 8, 5], state: "minecraft:clay"},
        {pos: [15, 8, 6], state: "minecraft:clay"},
        {pos: [15, 8, 7], state: "minecraft:clay"},
        {pos: [15, 8, 8], state: "minecraft:clay"},
        {pos: [15, 8, 9], state: "minecraft:cobblestone"},
        {pos: [15, 8, 10], state: "minecraft:cobblestone"},
        {pos: [15, 8, 14], state: "minecraft:moss_carpet"},
        {pos: [15, 8, 22], state: "minecraft:moss_carpet"},
        {pos: [15, 8, 23], state: "minecraft:moss_carpet"},
        {pos: [15, 8, 25], state: "minecraft:grass"},
        {pos: [15, 8, 29], state: "dustandash:cobblestone_with_moss"},
        {pos: [15, 8, 30], state: "minecraft:clay"},
        {pos: [15, 8, 31], state: "minecraft:stone"},
        {pos: [15, 8, 32], state: "minecraft:clay"},
        {pos: [15, 8, 33], state: "minecraft:stone"},
        {pos: [15, 8, 34], state: "minecraft:clay"},
        {pos: [15, 8, 35], state: "minecraft:clay"},
        {pos: [16, 8, 5], state: "minecraft:cobblestone"},
        {pos: [16, 8, 6], state: "minecraft:cobblestone"},
        {pos: [16, 8, 7], state: "minecraft:cobblestone"},
        {pos: [16, 8, 8], state: "minecraft:stone"},
        {pos: [16, 8, 9], state: "minecraft:clay"},
        {pos: [16, 8, 10], state: "minecraft:clay"},
        {pos: [16, 8, 15], state: "minecraft:grass"},
        {pos: [16, 8, 18], state: "minecraft:grass"},
        {pos: [16, 8, 21], state: "minecraft:tall_grass{half:upper}"},
        {pos: [16, 8, 30], state: "minecraft:cobblestone"},
        {pos: [16, 8, 31], state: "minecraft:clay"},
        {pos: [16, 8, 32], state: "minecraft:moss_block"},
        {pos: [16, 8, 33], state: "minecraft:cobblestone"},
        {pos: [16, 8, 34], state: "minecraft:clay"},
        {pos: [16, 8, 35], state: "minecraft:clay"},
        {pos: [17, 8, 5], state: "minecraft:clay"},
        {pos: [17, 8, 6], state: "minecraft:cobblestone"},
        {pos: [17, 8, 7], state: "minecraft:stone"},
        {pos: [17, 8, 8], state: "minecraft:cobblestone"},
        {pos: [17, 8, 9], state: "minecraft:clay"},
        {pos: [17, 8, 10], state: "minecraft:clay"},
        {pos: [17, 8, 11], state: "minecraft:moss_carpet"},
        {pos: [17, 8, 29], state: "minecraft:cobblestone"},
        {pos: [17, 8, 30], state: "minecraft:stone"},
        {pos: [17, 8, 31], state: "minecraft:cobblestone"},
        {pos: [17, 8, 32], state: "minecraft:water{level:0}"},
        {pos: [17, 8, 33], state: "minecraft:clay"},
        {pos: [17, 8, 34], state: "minecraft:cobblestone"},
        {pos: [17, 8, 35], state: "minecraft:clay"},
        {pos: [17, 8, 36], state: "minecraft:clay"},
        {pos: [18, 8, 5], state: "minecraft:clay"},
        {pos: [18, 8, 6], state: "minecraft:clay"},
        {pos: [18, 8, 7], state: "minecraft:cobblestone"},
        {pos: [18, 8, 8], state: "minecraft:clay"},
        {pos: [18, 8, 9], state: "minecraft:clay"},
        {pos: [18, 8, 29], state: "minecraft:cobblestone"},
        {pos: [18, 8, 30], state: "minecraft:water{level:3}"},
        {pos: [18, 8, 31], state: "minecraft:water{level:2}"},
        {pos: [18, 8, 32], state: "minecraft:water{level:1}"},
        {pos: [18, 8, 33], state: "minecraft:moss_block"},
        {pos: [18, 8, 34], state: "minecraft:clay"},
        {pos: [18, 8, 35], state: "minecraft:cobblestone"},
        {pos: [18, 8, 36], state: "minecraft:clay"},
        {pos: [19, 8, 5], state: "minecraft:clay"},
        {pos: [19, 8, 6], state: "minecraft:stone"},
        {pos: [19, 8, 7], state: "minecraft:clay"},
        {pos: [19, 8, 8], state: "minecraft:cobblestone"},
        {pos: [19, 8, 30], state: "minecraft:water{level:4}"},
        {pos: [19, 8, 31], state: "minecraft:water{level:3}"},
        {pos: [19, 8, 32], state: "minecraft:dirt"},
        {pos: [19, 8, 33], state: "minecraft:dirt"},
        {pos: [19, 8, 34], state: "dustandash:cobblestone_with_moss"},
        {pos: [19, 8, 35], state: "minecraft:moss_block"},
        {pos: [19, 8, 36], state: "minecraft:clay"},
        {pos: [19, 8, 37], state: "minecraft:clay"},
        {pos: [20, 8, 5], state: "minecraft:cobblestone"},
        {pos: [20, 8, 6], state: "minecraft:clay"},
        {pos: [20, 8, 7], state: "minecraft:clay"},
        {pos: [20, 8, 8], state: "minecraft:clay"},
        {pos: [20, 8, 30], state: "minecraft:water{level:5}"},
        {pos: [20, 8, 31], state: "minecraft:water{level:4}"},
        {pos: [20, 8, 32], state: "minecraft:moss_carpet"},
        {pos: [20, 8, 33], state: "minecraft:dirt"},
        {pos: [20, 8, 34], state: "minecraft:tall_grass{half:lower}"},
        {pos: [20, 8, 35], state: "minecraft:moss_block"},
        {pos: [20, 8, 36], state: "minecraft:clay"},
        {pos: [20, 8, 37], state: "minecraft:moss_block"},
        {pos: [21, 8, 5], state: "minecraft:clay"},
        {pos: [21, 8, 6], state: "minecraft:clay"},
        {pos: [21, 8, 7], state: "minecraft:cobblestone"},
        {pos: [21, 8, 8], state: "minecraft:clay"},
        {pos: [21, 8, 10], state: "minecraft:moss_carpet"},
        {pos: [21, 8, 32], state: "minecraft:moss_block"},
        {pos: [21, 8, 33], state: "minecraft:dirt"},
        {pos: [21, 8, 34], state: "minecraft:grass"},
        {pos: [21, 8, 35], state: "minecraft:moss_block"},
        {pos: [21, 8, 36], state: "minecraft:moss_block"},
        {pos: [21, 8, 37], state: "minecraft:moss_block"},
        {pos: [21, 8, 38], state: "minecraft:clay"},
        {pos: [22, 8, 5], state: "minecraft:clay"},
        {pos: [22, 8, 6], state: "minecraft:stone"},
        {pos: [22, 8, 7], state: "minecraft:clay"},
        {pos: [22, 8, 31], state: "minecraft:grass"},
        {pos: [22, 8, 33], state: "minecraft:moss_carpet"},
        {pos: [22, 8, 34], state: "minecraft:dirt"},
        {pos: [22, 8, 35], state: "minecraft:moss_block"},
        {pos: [22, 8, 36], state: "minecraft:moss_block"},
        {pos: [22, 8, 37], state: "minecraft:moss_block"},
        {pos: [22, 8, 38], state: "minecraft:clay"},
        {pos: [23, 8, 5], state: "minecraft:cobblestone"},
        {pos: [23, 8, 6], state: "minecraft:clay"},
        {pos: [23, 8, 7], state: "minecraft:clay"},
        {pos: [23, 8, 8], state: "minecraft:moss_carpet"},
        {pos: [23, 8, 31], state: "minecraft:grass"},
        {pos: [23, 8, 33], state: "minecraft:dirt"},
        {pos: [23, 8, 34], state: "minecraft:grass"},
        {pos: [23, 8, 35], state: "minecraft:moss_block"},
        {pos: [23, 8, 36], state: "minecraft:clay"},
        {pos: [23, 8, 37], state: "minecraft:cobblestone"},
        {pos: [23, 8, 38], state: "minecraft:clay"},
        {pos: [24, 8, 5], state: "minecraft:clay"},
        {pos: [24, 8, 6], state: "minecraft:clay"},
        {pos: [24, 8, 7], state: "minecraft:cobblestone"},
        {pos: [24, 8, 32], state: "minecraft:grass"},
        {pos: [24, 8, 34], state: "minecraft:dirt"},
        {pos: [24, 8, 35], state: "minecraft:cobblestone"},
        {pos: [24, 8, 36], state: "minecraft:stone"},
        {pos: [24, 8, 37], state: "minecraft:clay"},
        {pos: [24, 8, 38], state: "minecraft:clay"},
        {pos: [25, 8, 6], state: "minecraft:cobblestone"},
        {pos: [25, 8, 7], state: "minecraft:stone"},
        {pos: [25, 8, 8], state: "minecraft:clay"},
        {pos: [25, 8, 36], state: "minecraft:clay"},
        {pos: [25, 8, 37], state: "minecraft:cobblestone"},
        {pos: [25, 8, 38], state: "minecraft:clay"},
        {pos: [26, 8, 6], state: "minecraft:clay"},
        {pos: [26, 8, 7], state: "minecraft:clay"},
        {pos: [26, 8, 8], state: "minecraft:clay"},
        {pos: [26, 8, 9], state: "minecraft:clay"},
        {pos: [26, 8, 35], state: "minecraft:cobblestone"},
        {pos: [26, 8, 36], state: "dustandash:cobblestone_with_moss"},
        {pos: [26, 8, 37], state: "minecraft:clay"},
        {pos: [26, 8, 38], state: "minecraft:clay"},
        {pos: [27, 8, 6], state: "minecraft:clay"},
        {pos: [27, 8, 7], state: "minecraft:clay"},
        {pos: [27, 8, 8], state: "minecraft:clay"},
        {pos: [27, 8, 9], state: "minecraft:clay"},
        {pos: [27, 8, 10], state: "minecraft:moss_carpet"},
        {pos: [27, 8, 36], state: "minecraft:cobblestone"},
        {pos: [27, 8, 37], state: "minecraft:clay"},
        {pos: [27, 8, 38], state: "minecraft:clay"},
        {pos: [28, 8, 6], state: "minecraft:clay"},
        {pos: [28, 8, 7], state: "minecraft:cobblestone"},
        {pos: [28, 8, 8], state: "minecraft:clay"},
        {pos: [28, 8, 9], state: "minecraft:clay"},
        {pos: [28, 8, 10], state: "minecraft:clay"},
        {pos: [28, 8, 33], state: "dustandash:cobblestone_with_moss"},
        {pos: [28, 8, 36], state: "minecraft:stone"},
        {pos: [28, 8, 37], state: "minecraft:cobblestone"},
        {pos: [29, 8, 7], state: "minecraft:clay"},
        {pos: [29, 8, 8], state: "minecraft:clay"},
        {pos: [29, 8, 9], state: "minecraft:cobblestone"},
        {pos: [29, 8, 10], state: "minecraft:clay"},
        {pos: [29, 8, 11], state: "minecraft:clay"},
        {pos: [29, 8, 36], state: "minecraft:clay"},
        {pos: [29, 8, 37], state: "minecraft:clay"},
        {pos: [30, 8, 7], state: "minecraft:cobblestone"},
        {pos: [30, 8, 8], state: "minecraft:cobblestone"},
        {pos: [30, 8, 9], state: "minecraft:clay"},
        {pos: [30, 8, 10], state: "minecraft:clay"},
        {pos: [30, 8, 11], state: "minecraft:clay"},
        {pos: [30, 8, 12], state: "dustandash:cobblestone_with_moss"},
        {pos: [30, 8, 36], state: "minecraft:stone"},
        {pos: [30, 8, 37], state: "minecraft:clay"},
        {pos: [31, 8, 7], state: "minecraft:cobblestone"},
        {pos: [31, 8, 8], state: "minecraft:clay"},
        {pos: [31, 8, 9], state: "minecraft:clay"},
        {pos: [31, 8, 10], state: "minecraft:stone"},
        {pos: [31, 8, 11], state: "minecraft:cobblestone"},
        {pos: [31, 8, 12], state: "minecraft:clay"},
        {pos: [31, 8, 33], state: "minecraft:moss_carpet"},
        {pos: [31, 8, 36], state: "minecraft:cobblestone"},
        {pos: [31, 8, 37], state: "minecraft:clay"},
        {pos: [32, 8, 8], state: "minecraft:cobblestone"},
        {pos: [32, 8, 9], state: "minecraft:cobblestone"},
        {pos: [32, 8, 10], state: "minecraft:clay"},
        {pos: [32, 8, 11], state: "minecraft:clay"},
        {pos: [32, 8, 12], state: "dustandash:cobblestone_with_moss"},
        {pos: [32, 8, 36], state: "minecraft:clay"},
        {pos: [32, 8, 37], state: "minecraft:clay"},
        {pos: [33, 8, 9], state: "minecraft:clay"},
        {pos: [33, 8, 10], state: "minecraft:clay"},
        {pos: [33, 8, 11], state: "minecraft:stone"},
        {pos: [33, 8, 12], state: "minecraft:clay"},
        {pos: [33, 8, 34], state: "minecraft:glass"},
        {pos: [33, 8, 35], state: "minecraft:clay"},
        {pos: [33, 8, 36], state: "minecraft:cobblestone"},
        {pos: [33, 8, 37], state: "minecraft:clay"},
        {pos: [33, 8, 38], state: "minecraft:clay"},
        {pos: [34, 8, 9], state: "minecraft:clay"},
        {pos: [34, 8, 10], state: "minecraft:cobblestone"},
        {pos: [34, 8, 11], state: "minecraft:clay"},
        {pos: [34, 8, 12], state: "minecraft:cobblestone"},
        {pos: [34, 8, 13], state: "minecraft:clay"},
        {pos: [34, 8, 15], state: "minecraft:moss_carpet"},
        {pos: [34, 8, 34], state: "minecraft:glass"},
        {pos: [34, 8, 35], state: "minecraft:stone"},
        {pos: [34, 8, 36], state: "minecraft:cobblestone"},
        {pos: [34, 8, 37], state: "minecraft:clay"},
        {pos: [34, 8, 38], state: "minecraft:clay"},
        {pos: [35, 8, 9], state: "minecraft:cobblestone"},
        {pos: [35, 8, 10], state: "minecraft:clay"},
        {pos: [35, 8, 11], state: "minecraft:clay"},
        {pos: [35, 8, 12], state: "minecraft:clay"},
        {pos: [35, 8, 13], state: "minecraft:clay"},
        {pos: [35, 8, 32], state: "minecraft:clay"},
        {pos: [35, 8, 33], state: "minecraft:glass"},
        {pos: [35, 8, 34], state: "minecraft:glass"},
        {pos: [35, 8, 35], state: "minecraft:clay"},
        {pos: [35, 8, 36], state: "minecraft:clay"},
        {pos: [35, 8, 37], state: "minecraft:clay"},
        {pos: [35, 8, 38], state: "minecraft:clay"},
        {pos: [36, 8, 9], state: "minecraft:clay"},
        {pos: [36, 8, 10], state: "minecraft:clay"},
        {pos: [36, 8, 11], state: "minecraft:clay"},
        {pos: [36, 8, 12], state: "minecraft:cobblestone"},
        {pos: [36, 8, 13], state: "minecraft:clay"},
        {pos: [36, 8, 17], state: "minecraft:moss_carpet"},
        {pos: [36, 8, 33], state: "minecraft:soul_lantern{hanging:false,waterlogged:false}"},
        {pos: [36, 8, 34], state: "minecraft:clay"},
        {pos: [36, 8, 35], state: "minecraft:clay"},
        {pos: [36, 8, 36], state: "minecraft:cobblestone"},
        {pos: [36, 8, 37], state: "minecraft:clay"},
        {pos: [36, 8, 38], state: "minecraft:clay"},
        {pos: [37, 8, 10], state: "minecraft:clay"},
        {pos: [37, 8, 11], state: "minecraft:cobblestone"},
        {pos: [37, 8, 12], state: "minecraft:clay"},
        {pos: [37, 8, 13], state: "minecraft:stone"},
        {pos: [37, 8, 14], state: "minecraft:clay"},
        {pos: [37, 8, 30], state: "minecraft:moss_carpet"},
        {pos: [37, 8, 32], state: "minecraft:cobblestone"},
        {pos: [37, 8, 34], state: "minecraft:clay"},
        {pos: [37, 8, 35], state: "minecraft:cobblestone"},
        {pos: [37, 8, 36], state: "minecraft:clay"},
        {pos: [37, 8, 37], state: "minecraft:clay"},
        {pos: [37, 8, 38], state: "minecraft:clay"},
        {pos: [38, 8, 11], state: "minecraft:clay"},
        {pos: [38, 8, 12], state: "minecraft:clay"},
        {pos: [38, 8, 13], state: "minecraft:cobblestone"},
        {pos: [38, 8, 14], state: "minecraft:clay"},
        {pos: [38, 8, 15], state: "minecraft:clay"},
        {pos: [38, 8, 19], state: "minecraft:moss_carpet"},
        {pos: [38, 8, 33], state: "minecraft:clay"},
        {pos: [38, 8, 34], state: "minecraft:stone"},
        {pos: [38, 8, 35], state: "minecraft:clay"},
        {pos: [38, 8, 36], state: "minecraft:cobblestone"},
        {pos: [38, 8, 37], state: "minecraft:clay"},
        {pos: [39, 8, 12], state: "minecraft:clay"},
        {pos: [39, 8, 13], state: "minecraft:clay"},
        {pos: [39, 8, 14], state: "minecraft:stone"},
        {pos: [39, 8, 15], state: "minecraft:cobblestone"},
        {pos: [39, 8, 16], state: "minecraft:clay"},
        {pos: [39, 8, 28], state: "minecraft:moss_carpet"},
        {pos: [39, 8, 32], state: "minecraft:stone"},
        {pos: [39, 8, 33], state: "minecraft:clay"},
        {pos: [39, 8, 34], state: "minecraft:cobblestone"},
        {pos: [39, 8, 35], state: "minecraft:clay"},
        {pos: [39, 8, 36], state: "minecraft:clay"},
        {pos: [40, 8, 13], state: "minecraft:clay"},
        {pos: [40, 8, 14], state: "minecraft:clay"},
        {pos: [40, 8, 15], state: "minecraft:clay"},
        {pos: [40, 8, 16], state: "minecraft:cobblestone"},
        {pos: [40, 8, 17], state: "minecraft:stone"},
        {pos: [40, 8, 18], state: "dustandash:cobblestone_with_moss"},
        {pos: [40, 8, 19], state: "minecraft:cobblestone"},
        {pos: [40, 8, 20], state: "dustandash:cobblestone_with_moss"},
        {pos: [40, 8, 21], state: "minecraft:clay"},
        {pos: [40, 8, 22], state: "minecraft:clay"},
        {pos: [40, 8, 23], state: "minecraft:clay"},
        {pos: [40, 8, 24], state: "dustandash:cobblestone_with_moss"},
        {pos: [40, 8, 25], state: "minecraft:clay"},
        {pos: [40, 8, 26], state: "minecraft:clay"},
        {pos: [40, 8, 27], state: "minecraft:stone"},
        {pos: [40, 8, 28], state: "dustandash:cobblestone_with_moss"},
        {pos: [40, 8, 29], state: "minecraft:stone"},
        {pos: [40, 8, 30], state: "dustandash:cobblestone_with_moss"},
        {pos: [40, 8, 31], state: "minecraft:clay"},
        {pos: [40, 8, 32], state: "minecraft:clay"},
        {pos: [40, 8, 33], state: "minecraft:clay"},
        {pos: [40, 8, 34], state: "minecraft:clay"},
        {pos: [40, 8, 35], state: "minecraft:clay"},
        {pos: [41, 8, 14], state: "minecraft:clay"},
        {pos: [41, 8, 15], state: "minecraft:clay"},
        {pos: [41, 8, 16], state: "minecraft:clay"},
        {pos: [41, 8, 17], state: "minecraft:cobblestone"},
        {pos: [41, 8, 18], state: "minecraft:clay"},
        {pos: [41, 8, 19], state: "minecraft:cobblestone"},
        {pos: [41, 8, 20], state: "minecraft:stone"},
        {pos: [41, 8, 21], state: "minecraft:clay"},
        {pos: [41, 8, 22], state: "minecraft:clay"},
        {pos: [41, 8, 23], state: "minecraft:stone"},
        {pos: [41, 8, 24], state: "minecraft:cobblestone"},
        {pos: [41, 8, 25], state: "minecraft:clay"},
        {pos: [41, 8, 26], state: "minecraft:cobblestone"},
        {pos: [41, 8, 27], state: "minecraft:clay"},
        {pos: [41, 8, 28], state: "minecraft:cobblestone"},
        {pos: [41, 8, 29], state: "minecraft:clay"},
        {pos: [41, 8, 30], state: "minecraft:clay"},
        {pos: [41, 8, 31], state: "minecraft:cobblestone"},
        {pos: [41, 8, 32], state: "minecraft:cobblestone"},
        {pos: [42, 8, 16], state: "minecraft:clay"},
        {pos: [42, 8, 17], state: "minecraft:clay"},
        {pos: [42, 8, 18], state: "minecraft:clay"},
        {pos: [42, 8, 19], state: "minecraft:clay"},
        {pos: [42, 8, 20], state: "minecraft:clay"},
        {pos: [42, 8, 21], state: "minecraft:clay"},
        {pos: [42, 8, 22], state: "minecraft:cobblestone"},
        {pos: [42, 8, 23], state: "minecraft:clay"},
        {pos: [42, 8, 24], state: "minecraft:clay"},
        {pos: [42, 8, 25], state: "minecraft:clay"},
        {pos: [42, 8, 26], state: "minecraft:cobblestone"},
        {pos: [42, 8, 27], state: "minecraft:clay"},
        {pos: [42, 8, 28], state: "minecraft:clay"},
        {pos: [42, 8, 29], state: "minecraft:clay"},
        {pos: [42, 8, 30], state: "minecraft:clay"},
        {pos: [42, 8, 31], state: "minecraft:clay"},
        {pos: [43, 8, 20], state: "minecraft:clay"},
        {pos: [43, 8, 21], state: "minecraft:clay"},
        {pos: [43, 8, 22], state: "minecraft:clay"},
        {pos: [43, 8, 23], state: "minecraft:clay"},
        {pos: [43, 8, 24], state: "minecraft:clay"},
        {pos: [43, 8, 25], state: "minecraft:clay"},
        {pos: [43, 8, 26], state: "minecraft:clay"},
        {pos: [43, 8, 27], state: "minecraft:clay"},
        {pos: [43, 8, 28], state: "minecraft:clay"},
        {pos: [11, 9, 17], state: "minecraft:cobblestone"},
        {pos: [12, 9, 11], state: "minecraft:cobblestone"},
        {pos: [12, 9, 12], state: "minecraft:stone"},
        {pos: [12, 9, 14], state: "minecraft:stone"},
        {pos: [12, 9, 19], state: "minecraft:stone"},
        {pos: [12, 9, 22], state: "minecraft:cobblestone"},
        {pos: [13, 9, 16], state: "minecraft:cobblestone"},
        {pos: [13, 9, 17], state: "minecraft:moss_carpet"},
        {pos: [13, 9, 23], state: "minecraft:cobblestone"},
        {pos: [13, 9, 28], state: "minecraft:cobblestone"},
        {pos: [14, 9, 9], state: "minecraft:stone"},
        {pos: [14, 9, 26], state: "minecraft:cobblestone"},
        {pos: [14, 9, 31], state: "minecraft:stone"},
        {pos: [14, 9, 32], state: "minecraft:cobblestone"},
        {pos: [15, 9, 30], state: "minecraft:cobblestone"},
        {pos: [16, 9, 8], state: "minecraft:stone"},
        {pos: [16, 9, 34], state: "minecraft:dirt"},
        {pos: [16, 9, 35], state: "minecraft:cobblestone"},
        {pos: [17, 9, 6], state: "minecraft:cobblestone"},
        {pos: [17, 9, 31], state: "minecraft:dirt"},
        {pos: [17, 9, 33], state: "minecraft:moss_carpet"},
        {pos: [18, 9, 8], state: "minecraft:stone"},
        {pos: [18, 9, 34], state: "minecraft:cobblestone"},
        {pos: [19, 9, 33], state: "minecraft:dirt"},
        {pos: [20, 9, 6], state: "minecraft:cobblestone"},
        {pos: [20, 9, 34], state: "minecraft:tall_grass{half:upper}"},
        {pos: [20, 9, 36], state: "minecraft:dirt"},
        {pos: [21, 9, 32], state: "minecraft:grass"},
        {pos: [21, 9, 36], state: "minecraft:grass"},
        {pos: [21, 9, 37], state: "minecraft:flowering_azalea"},
        {pos: [22, 9, 6], state: "minecraft:stone"},
        {pos: [22, 9, 35], state: "minecraft:tall_grass{half:lower}"},
        {pos: [22, 9, 36], state: "minecraft:moss_carpet"},
        {pos: [23, 9, 7], state: "minecraft:cobblestone"},
        {pos: [23, 9, 35], state: "minecraft:stone"},
        {pos: [23, 9, 36], state: "minecraft:cobblestone"},
        {pos: [24, 9, 38], state: "minecraft:cobblestone"},
        {pos: [25, 9, 8], state: "minecraft:stone"},
        {pos: [26, 9, 7], state: "minecraft:cobblestone"},
        {pos: [26, 9, 36], state: "minecraft:stone"},
        {pos: [28, 9, 8], state: "minecraft:stone"},
        {pos: [29, 9, 11], state: "minecraft:cobblestone"},
        {pos: [29, 9, 36], state: "minecraft:cobblestone"},
        {pos: [30, 9, 37], state: "minecraft:cobblestone"},
        {pos: [31, 9, 8], state: "minecraft:cobblestone"},
        {pos: [31, 9, 9], state: "minecraft:stone"},
        {pos: [31, 9, 36], state: "minecraft:cobblestone"},
        {pos: [33, 9, 12], state: "minecraft:stone"},
        {pos: [33, 9, 35], state: "minecraft:cobblestone"},
        {pos: [33, 9, 36], state: "minecraft:stone"},
        {pos: [35, 9, 37], state: "minecraft:cobblestone"},
        {pos: [36, 9, 11], state: "minecraft:cobblestone"},
        {pos: [36, 9, 12], state: "minecraft:stone"},
        {pos: [36, 9, 34], state: "minecraft:glass"},
        {pos: [36, 9, 35], state: "minecraft:cobblestone"},
        {pos: [38, 9, 33], state: "minecraft:stone"},
        {pos: [38, 9, 35], state: "minecraft:cobblestone"},
        {pos: [39, 9, 12], state: "minecraft:cobblestone"},
        {pos: [39, 9, 14], state: "minecraft:stone"},
        {pos: [39, 9, 16], state: "minecraft:stone"},
        {pos: [40, 9, 22], state: "minecraft:moss_carpet"},
        {pos: [40, 9, 32], state: "minecraft:cobblestone"},
        {pos: [41, 9, 16], state: "minecraft:cobblestone"},
        {pos: [41, 9, 20], state: "minecraft:stone"},
        {pos: [41, 9, 21], state: "minecraft:cobblestone"},
        {pos: [41, 9, 25], state: "minecraft:moss_carpet"},
        {pos: [41, 9, 28], state: "minecraft:stone"},
        {pos: [41, 9, 30], state: "minecraft:stone"},
        {pos: [42, 9, 26], state: "minecraft:cobblestone"},
        {pos: [18, 10, 34], state: "minecraft:dirt"},
        {pos: [19, 10, 33], state: "minecraft:soul_lantern{hanging:false,waterlogged:false}"},
        {pos: [22, 10, 35], state: "minecraft:tall_grass{half:upper}"},
        {pos: [35, 10, 37], state: "minecraft:stone"},
        {pos: [36, 10, 35], state: "minecraft:stone"},
        {pos: [42, 10, 26], state: "minecraft:cobblestone"}
    ],
    entities: [],
    palette: [
        "dustandash:cobblestone_with_moss",
        "minecraft:moss_block",
        "minecraft:cobblestone",
        "minecraft:stone",
        "minecraft:hay_block{axis:y}",
        "minecraft:hay_block{axis:z}",
        "minecraft:hay_block{axis:x}",
        "minecraft:clay",
        "minecraft:dirt",
        "quark:azalea_planks_slab{type:double,waterlogged:false}",
        "minecraft:glass",
        "minecraft:hanging_roots{waterlogged:false}",
        "minecraft:moss_carpet",
        "minecraft:grass",
        "minecraft:tall_grass{half:lower}",
        "minecraft:azalea",
        "minecraft:composter{level:5}",
        "quark:azalea_fence{east:false,north:false,south:false,waterlogged:false,west:false}",
        "quark:azalea_fence{east:false,north:false,south:true,waterlogged:false,west:false}",
        "minecraft:water{level:8}",
        "minecraft:tall_grass{half:upper}",
        "quark:azalea_fence{east:true,north:false,south:false,waterlogged:false,west:false}",
        "quark:azalea_fence{east:false,north:false,south:false,waterlogged:false,west:true}",
        "minecraft:flowering_azalea",
        "minecraft:lantern{hanging:true,waterlogged:false}",
        "minecraft:water{level:1}",
        "quark:azalea_planks_slab{type:bottom,waterlogged:false}",
        "quark:azalea_planks_slab{type:top,waterlogged:false}",
        "minecraft:water{level:0}",
        "minecraft:water{level:3}",
        "minecraft:water{level:2}",
        "minecraft:water{level:4}",
        "minecraft:water{level:5}",
        "minecraft:soul_lantern{hanging:false,waterlogged:false}",
        "quark:azalea_chest{facing:north,type:left,waterlogged:false}",
        "quark:azalea_chest{facing:north,type:right,waterlogged:false}"
    ]
}